Workbook

Sheet FD
A1: Country | C1: Country code | D1: Data type | E1: 2000 | F1: 2001 | G1: 2002 | H1: 2003 | I1: 2004 | J1: 2005 | K1: 2006 | L1: 2007 | M1: 2008 | N1: 2009 | O1: 2010 | P1: 2011 | Q1: 2012 | R1: 2013 | S1: 2014 | T1: 2015 | U1: 2016 | V1: 2017 | W1: 2018 | X1: 2019 | Y1: 2020 | Z1: 2021 | AC1: AVERAGE
A2: Angola | C2: AGO | D2: Financial Development Index | E2: 0.09 | F2: 0.09 | G2: 0.1 | H2: 0.1 | I2: 0.11 | J2: 0.11 | K2: 0.12 | L2: 0.13 | M2: 0.14 | N2: 0.16 | O2: 0.15 | P2: 0.14 | Q2: 0.13 | R2: 0.14 | S2: 0.13 | T2: 0.15 | U2: 0.15 | V2: 0.15 | W2: 0.14 | X2: 0.1 | Y2: 0.13 | Z2: 0.14 | AC2: =AVERAGE(E2:Z2) -> 0.12727273
A3: Bangladesh | C3: BGD | D3: Financial Development Index | E3: 0.22 | F3: 0.19 | G3: 0.2 | H3: 0.21 | I3: 0.19 | J3: 0.16 | K3: 0.14 | L3: 0.15 | M3: 0.19 | N3: 0.2 | O3: 0.23 | P3: 0.21 | Q3: 0.2 | R3: 0.21 | S3: 0.26 | T3: 0.25 | U3: 0.25 | V3: 0.28 | W3: 0.25 | X3: 0.25 | Y3: 0.24 | Z3: 0.24 | AC3: =AVERAGE(E3:Z3) -> 0.21454545
A4: Bolivia | C4: BOL | D4: Financial Development Index | E4: 0.11 | F4: 0.11 | G4: 0.12 | H4: 0.15 | I4: 0.15 | J4: 0.15 | K4: 0.16 | L4: 0.18 | M4: 0.18 | N4: 0.2 | O4: 0.2 | P4: 0.22 | Q4: 0.23 | R4: 0.24 | S4: 0.26 | T4: 0.28 | U4: 0.3 | V4: 0.31 | W4: 0.32 | X4: 0.33 | Y4: 0.35 | Z4: 0.39 | AC4: =AVERAGE(E4:Z4) -> 0.22454545
A5: Cameroon | C5: CMR | D5: Financial Development Index | E5: 0.08 | F5: 0.08 | G5: 0.08 | H5: 0.07 | I5: 0.07 | J5: 0.08 | K5: 0.08 | L5: 0.09 | M5: 0.09 | N5: 0.08 | O5: 0.08 | P5: 0.08 | Q5: 0.08 | R5: 0.1 | S5: 0.08 | T5: 0.08 | U5: 0.08 | V5: 0.09 | W5: 0.09 | X5: 0.09 | Y5: 0.09 | Z5: 0.1 | AC5: =AVERAGE(E5:Z5) -> 0.083636364
A6: Congo, Rep. of | C6: COG | D6: Financial Development Index | E6: 0.04 | F6: 0.05 | G6: 0.04 | H6: 0.06 | I6: 0.04 | J6: 0.03 | K6: 0.03 | L6: 0.03 | M6: 0.04 | N6: 0.08 | O6: 0.09 | P6: 0.08 | Q6: 0.09 | R6: 0.09 | S6: 0.1 | T6: 0.12 | U6: 0.12 | V6: 0.12 | W6: 0.1 | X6: 0.1 | Y6: 0.1 | Z6: 0.09 | AC6: =AVERAGE(E6:Z6) -> 0.074545455
A7: Côte d'Ivoire | C7: CIV | D7: Financial Development Index | E7: 0.14 | F7: 0.12 | G7: 0.1 | H7: 0.1 | I7: 0.11 | J7: 0.11 | K7: 0.13 | L7: 0.14 | M7: 0.14 | N7: 0.14 | O7: 0.15 | P7: 0.13 | Q7: 0.15 | R7: 0.16 | S7: 0.16 | T7: 0.17 | U7: 0.17 | V7: 0.17 | W7: 0.15 | X7: 0.14 | Y7: 0.13 | Z7: 0.13 | AC7: =AVERAGE(E7:Z7) -> 0.13818182
A8: Egypt, Arab Rep. of | C8: EGY | D8: Financial Development Index | E8: 0.3 | F8: 0.31 | G8: 0.33 | H8: 0.33 | I8: 0.34 | J8: 0.42 | K8: 0.37 | L8: 0.37 | M8: 0.43 | N8: 0.4 | O8: 0.32 | P8: 0.28 | Q8: 0.27 | R8: 0.26 | S8: 0.29 | T8: 0.27 | U8: 0.3 | V8: 0.29 | W8: 0.29 | X8: 0.3 | Y8: 0.3 | Z8: 0.31 | AC8: =AVERAGE(E8:Z8) -> 0.32181818
A9: Ghana | C9: GHA | D9: Financial Development Index | E9: 0.12 | F9: 0.12 | G9: 0.11 | H9: 0.12 | I9: 0.14 | J9: 0.12 | K9: 0.11 | L9: 0.12 | M9: 0.13 | N9: 0.11 | O9: 0.12 | P9: 0.13 | Q9: 0.15 | R9: 0.15 | S9: 0.16 | T9: 0.16 | U9: 0.17 | V9: 0.17 | W9: 0.17 | X9: 0.18 | Y9: 0.17 | Z9: 0.18 | AC9: =AVERAGE(E9:Z9) -> 0.14136364
A10: Haiti | C10: HTI | D10: Financial Development Index | E10: 0.09 | F10: 0.09 | G10: 0.09 | H10: 0.09 | I10: 0.09 | J10: 0.06 | K10: 0.06 | L10: 0.06 | M10: 0.06 | N10: 0.08 | O10: 0.08 | P10: 0.09 | Q10: 0.1 | R10: 0.1 | S10: 0.1 | T10: 0.1 | U10: 0.1 | V10: 0.1 | W10: 0.1 | X10: 0.1 | Y10: 0.09 | Z10: 0.1 | AC10: =AVERAGE(E10:Z10) -> 0.087727273
A11: Honduras | C11: HND | D11: Financial Development Index | E11: 0.13 | F11: 0.15 | G11: 0.14 | H11: 0.16 | I11: 0.15 | J11: 0.16 | K11: 0.18 | L11: 0.19 | M11: 0.2 | N11: 0.19 | O11: 0.18 | P11: 0.18 | Q11: 0.2 | R11: 0.2 | S11: 0.2 | T11: 0.2 | U11: 0.21 | V11: 0.21 | W11: 0.21 | X11: 0.21 | Y11: 0.21 | Z11: 0.21 | AC11: =AVERAGE(E11:Z11) -> 0.185
A12: India | C12: IND | D12: Financial Development Index | E12: 0.44 | F12: 0.42 | G12: 0.43 | H12: 0.43 | I12: 0.45 | J12: 0.45 | K12: 0.47 | L12: 0.45 | M12: 0.48 | N12: 0.51 | O12: 0.48 | P12: 0.44 | Q12: 0.42 | R12: 0.42 | S12: 0.44 | T12: 0.44 | U12: 0.45 | V12: 0.46 | W12: 0.47 | X12: 0.47 | Y12: 0.54 | Z12: 0.53 | AC12: =AVERAGE(E12:Z12) -> 0.45863636
A13: Jordan | C13: JOR | D13: Financial Development Index | E13: 0.53 | F13: 0.53 | G13: 0.53 | H13: 0.52 | I13: 0.53 | J13: 0.54 | K13: 0.5 | L13: 0.51 | M13: 0.58 | N13: 0.5 | O13: 0.46 | P13: 0.42 | Q13: 0.4 | R13: 0.39 | S13: 0.37 | T13: 0.37 | U13: 0.37 | V13: 0.37 | W13: 0.38 | X13: 0.36 | Y13: 0.35 | Z13: 0.36 | AC13: =AVERAGE(E13:Z13) -> 0.44863636
... A28: Zambia | C28: ZMB | D28: Financial Development Index | E28: 0.14 | F28: 0.14 | G28: 0.17 | H28: 0.14 | I28: 0.16 | J28: 0.15 | K28: 0.17 | L28: 0.18 | M28: 0.18 | N28: 0.16 | O28: 0.17 | P28: 0.19 | Q28: 0.19 | R28: 0.19 | S28: 0.18 | T28: 0.19 | U28: 0.19 | V28: 0.19 | W28: 0.19 | X28: 0.19 | Y28: 0.2 | Z28: 0.2 | AC28: =AVERAGE(E28:Z28) -> 0.17545455
A33: Source: | D33: https://data.imf.org/?sk=f8032e80-b36c-43b1-ac26-493c5b1cd33b&sid=1480712464593
D34: (International Monetary Fund)

Sheet FD all indicators
A1: Financial Development (FD)
C2: 2000 | D2: 2001 | E2: 2002 | F2: 2003 | G2: 2004 | H2: 2005 | I2: 2006 | J2: 2007 | K2: 2008 | L2: 2009 | M2: 2010 | N2: 2011 | O2: 2012 | P2: 2013 | Q2: 2014 | R2: 2015 | S2: 2016 | T2: 2017 | U2: 2018 | V2: 2019 | W2: 2020 | X2: 2021
A3: Angola | B3: Financial Development Index | C3: 0.09 | D3: 0.09 | E3: 0.1 | F3: 0.1 | G3: 0.11 | H3: 0.11 | I3: 0.12 | J3: 0.13 | K3: 0.14 | L3: 0.16 | M3: 0.15 | N3: 0.14 | O3: 0.13 | P3: 0.14 | Q3: 0.13 | R3: 0.15 | S3: 0.15 | T3: 0.15 | U3: 0.14 | V3: 0.1 | W3: 0.13 | X3: 0.14
B4: Financial Institutions Access Index | C4: 0.02 | D4: 0.02 | E4: 0.02 | F4: 0.02 | G4: 0.03 | H4: 0.03 | I4: 0.05 | J4: 0.06 | K4: 0.08 | L4: 0.1 | M4: 0.13 | N4: 0.15 | O4: 0.17 | P4: 0.19 | Q4: 0.2 | R4: 0.21 | S4: 0.2 | T4: 0.21 | U4: 0.19 | V4: 0.19 | W4: 0.18 | X4: 0.17
B5: Financial Institutions Depth Index | C5: 0.03 | D5: 0.03 | E5: 0.05 | F5: 0.06 | G5: 0.05 | H5: 0.05 | I5: 0.04 | J5: 0.04 | K5: 0.04 | L5: 0.07 | M5: 0.07 | N5: 0.06 | O5: 0.06 | P5: 0.06 | Q5: 0.06 | R5: 0.07 | S5: 0.06 | T5: 0.05 | U5: 0.04 | V5: 0.05 | W5: 0.04 | X5: 0.04
B6: Financial Institutions Efficiency Index | C6: 0.4 | D6: 0.38 | E6: 0.42 | F6: 0.4 | G6: 0.41 | H6: 0.42 | I6: 0.51 | J6: 0.61 | K6: 0.72 | L6: 0.7 | M6: 0.68 | N6: 0.61 | O6: 0.54 | P6: 0.56 | Q6: 0.46 | R6: 0.52 | S6: 0.56 | T6: 0.57 | U6: 0.57 | V6: 0.18 | W6: 0.36 | X6: 0.58
B7: Financial Institutions Index | C7: 0.13 | D7: 0.13 | E7: 0.14 | F7: 0.14 | G7: 0.14 | H7: 0.15 | I7: 0.18 | J7: 0.21 | K7: 0.25 | L7: 0.26 | M7: 0.27 | N7: 0.26 | O7: 0.25 | P7: 0.26 | Q7: 0.24 | R7: 0.26 | S7: 0.26 | T7: 0.26 | U7: 0.26 | V7: 0.15 | W7: 0.2 | X7: 0.25
B8: Financial Markets Access Index | C8: 0.01 | D8: 0.01 | E8: 0.01 | F8: 0.01 | G8: 0.01 | H8: 0.01 | I8: 0.01 | J8: 0.01 | K8: 0.01 | L8: 0.01 | M8: 0.01 | N8: 0.01 | O8: 0.01 | P8: 0.01 | Q8: 0.01 | R8: 0.01 | S8: 0.01 | T8: 0 | U8: 0 | V8: 0 | W8: 0.01 | X8: 0
B9: Financial Markets Depth Index | C9: 0.14 | D9: 0.15 | E9: 0.15 | F9: 0.15 | G9: 0.18 | H9: 0.15 | I9: 0.11 | J9: 0.09 | K9: 0.07 | L9: 0.1 | M9: 0.07 | N9: 0.05 | O9: 0.03 | P9: 0.05 | Q9: 0.06 | R9: 0.08 | S9: 0.09 | T9: 0.07 | U9: 0.07 | V9: 0.1 | W9: 0.16 | X9: 0.06
B10: Financial Markets Efficiency Index | C10: 0 | D10: 0 | E10: 0 | F10: 0 | G10: 0 | H10: 0 | I10: 0 | J10: 0 | K10: 0 | L10: 0 | M10: 0 | N10: 0 | O10: 0 | P10: 0 | Q10: 0 | R10: 0 | S10: 0 | T10: 0 | U10: 0 | V10: 0 | W10: 0 | X10: 0
B11: Financial Markets Index | C11: 0.06 | D11: 0.06 | E11: 0.06 | F11: 0.06 | G11: 0.07 | H11: 0.06 | I11: 0.05 | J11: 0.04 | K11: 0.03 | L11: 0.04 | M11: 0.03 | N11: 0.02 | O11: 0.01 | P11: 0.02 | Q11: 0.03 | R11: 0.03 | S11: 0.04 | T11: 0.03 | U11: 0.03 | V11: 0.04 | W11: 0.06 | X11: 0.02
A12: Bangladesh | B12: Financial Development Index | C12: 0.22 | D12: 0.19 | E12: 0.2 | F12: 0.21 | G12: 0.19 | H12: 0.16 | I12: 0.14 | J12: 0.15 | K12: 0.19 | L12: 0.2 | M12: 0.23 | N12: 0.21 | O12: 0.2 | P12: 0.21 | Q12: 0.26 | R12: 0.25 | S12: 0.25 | T12: 0.28 | U12: 0.25 | V12: 0.25 | W12: 0.24 | X12: 0.24
B13: Financial Institutions Access Index | C13: 0.08 | D13: 0.09 | E13: 0.09 | F13: 0.08 | G13: 0.08 | H13: 0.08 | I13: 0.09 | J13: 0.09 | K13: 0.09 | L13: 0.09 | M13: 0.1 | N13: 0.11 | O13: 0.11 | P13: 0.12 | Q13: 0.12 | R13: 0.13 | S13: 0.14 | T13: 0.14 | U13: 0.14 | V13: 0.15 | W13: 0.15 | X13: 0.16
B14: Financial Institutions Depth Index | C14: 0.05 | D14: 0.05 | E14: 0.06 | F14: 0.06 | G14: 0.07 | H14: 0.07 | I14: 0.08 | J14: 0.08 | K14: 0.08 | L14: 0.09 | M14: 0.1 | N14: 0.1 | O14: 0.1 | P14: 0.1 | Q14: 0.1 | R14: 0.1 | S14: 0.1 | T14: 0.1 | U14: 0.1 | V14: 0.1 | W14: 0.1 | X14: 0.1
B15: Financial Institutions Efficiency Index | C15: 0.53 | D15: 0.58 | E15: 0.56 | F15: 0.6 | G15: 0.46 | H15: 0.62 | I15: 0.44 | J15: 0.44 | K15: 0.63 | L15: 0.64 | M15: 0.64 | N15: 0.65 | O15: 0.54 | P15: 0.67 | Q15: 0.65 | R15: 0.64 | S15: 0.62 | T15: 0.64 | U15: 0.66 | V15: 0.66 | W15: 0.66 | X15: 0.66
B16: Financial Institutions Index | C16: 0.2 | D16: 0.22 | E16: 0.21 | F16: 0.23 | G16: 0.19 | H16: 0.24 | I16: 0.19 | J16: 0.19 | K16: 0.24 | L16: 0.25 | M16: 0.26 | N16: 0.27 | O16: 0.24 | P16: 0.27 | Q16: 0.27 | R16: 0.27 | S16: 0.27 | T16: 0.28 | U16: 0.28 | V16: 0.28 | W16: 0.29 | X16: 0.29
B17: Financial Markets Access Index | C17: 0.16 | D17: 0.16 | E17: 0.16 | F17: 0.15 | G17: 0.15 | H17: 0.15 | I17: 0.16 | J17: 0.16 | K17: 0.18 | L17: 0.25 | M17: 0.33 | N17: 0.31 | O17: 0.29 | P17: 0.28 | Q17: 0.3 | R17: 0.29 | S17: 0.3 | T17: 0.35 | U17: 0.3 | V17: 0.3 | W17: 0.3 | X17: 0.3
B18: Financial Markets Depth Index | C18: 0.02 | D18: 0.01 | E18: 0.07 | F18: 0.07 | G18: 0.07 | H18: 0.01 | I18: 0.02 | J18: 0.03 | K18: 0.04 | L18: 0.06 | M18: 0.11 | N18: 0.1 | O18: 0.1 | P18: 0.09 | Q18: 0.14 | R18: 0.11 | S18: 0.09 | T18: 0.11 | U18: 0.08 | V18: 0.07 | W18: 0.08 | X18: 0.08
B19: Financial Markets Efficiency Index | C19: 0.53 | D19: 0.33 | E19: 0.33 | F19: 0.33 | G19: 0.33 | H19: 0.08 | I19: 0.08 | J19: 0.1 | K19: 0.15 | L19: 0.14 | M19: 0.14 | N19: 0.06 | O19: 0.06 | P19: 0.03 | Q19: 0.29 | R19: 0.26 | S19: 0.27 | T19: 0.38 | U19: 0.26 | V19: 0.25 | W19: 0.21 | X19: 0.21
B20: Financial Markets Index | C20: 0.22 | D20: 0.16 | E20: 0.18 | F20: 0.18 | G20: 0.18 | H20: 0.08 | I20: 0.08 | J20: 0.1 | K20: 0.12 | L20: 0.15 | M20: 0.19 | N20: 0.15 | O20: 0.15 | P20: 0.13 | Q20: 0.24 | R20: 0.22 | S20: 0.21 | T20: 0.27 | U20: 0.21 | V20: 0.2 | W20: 0.19 | X20: 0.19
A21: Bolivia | B21: Financial Development Index | C21: 0.11 | D21: 0.11 | E21: 0.12 | F21: 0.15 | G21: 0.15 | H21: 0.15 | I21: 0.16 | J21: 0.18 | K21: 0.18 | L21: 0.2 | M21: 0.2 | N21: 0.22 | O21: 0.23 | P21: 0.24 | Q21: 0.26 | R21: 0.28 | S21: 0.3 | T21: 0.31 | U21: 0.32 | V21: 0.33 | W21: 0.35 | X21: 0.39
B22: Financial Institutions Access Index | C22: 0.08 | D22: 0.08 | E22: 0.09 | F22: 0.09 | G22: 0.1 | H22: 0.11 | I22: 0.12 | J22: 0.24 | K22: 0.25 | L22: 0.29 | M22: 0.33 | N22: 0.39 | O22: 0.42 | P22: 0.48 | Q22: 0.53 | R22: 0.57 | S22: 0.63 | T22: 0.65 | U22: 0.66 | V22: 0.68 | W22: 0.69 | X22: 0.69
B23: Financial Institutions Depth Index | C23: 0.21 | D23: 0.21 | E23: 0.24 | F23: 0.26 | G23: 0.25 | H23: 0.25 | I23: 0.22 | J23: 0.21 | K23: 0.22 | L23: 0.25 | M23: 0.25 | N23: 0.25 | O23: 0.26 | P23: 0.28 | Q23: 0.29 | R23: 0.34 | S23: 0.38 | T23: 0.38 | U23: 0.4 | V23: 0.42 | W23: 0.49 | X23: 0.69
B24: Financial Institutions Efficiency Index | C24: 0.3 | D24: 0.3 | E24: 0.31 | F24: 0.47 | G24: 0.47 | H24: 0.43 | I24: 0.58 | J24: 0.54 | K24: 0.53 | L24: 0.55 | M24: 0.53 | N24: 0.55 | O24: 0.56 | P24: 0.51 | Q24: 0.55 | R24: 0.54 | S24: 0.56 | T24: 0.58 | U24: 0.59 | V24: 0.59 | W24: 0.62 | X24: 0.6
B25: Financial Institutions Index | C25: 0.21 | D25: 0.21 | E25: 0.23 | F25: 0.28 | G25: 0.28 | H25: 0.27 | I25: 0.31 | J25: 0.34 | K25: 0.35 | L25: 0.38 | M25: 0.39 | N25: 0.43 | O25: 0.45 | P25: 0.46 | Q25: 0.5 | R25: 0.54 | S25: 0.59 | T25: 0.6 | U25: 0.61 | V25: 0.64 | W25: 0.68 | X25: 0.76
B26: Financial Markets Access Index | C26: 0.02 | D26: 0.02 | E26: 0.02 | F26: 0.02 | G26: 0.02 | H26: 0.02 | I26: 0.02 | J26: 0.02 | K26: 0.02 | L26: 0.02 | M26: 0.02 | N26: 0.02 | O26: 0.02 | P26: 0.02 | Q26: 0.02 | R26: 0.02 | S26: 0.02 | T26: 0.02 | U26: 0.02 | V26: 0.01 | W26: 0.01 | X26: 0.01
B27: Financial Markets Depth Index | C27: 0.01 | D27: 0.01 | E27: 0.01 | F27: 0.01 | G27: 0.02 | H27: 0.02 | I27: 0.02 | J27: 0.02 | K27: 0.01 | L27: 0.01 | M27: 0.01 | N27: 0.01 | O27: 0.01 | P27: 0.01 | Q27: 0.01 | R27: 0.01 | S27: 0.01 | T27: 0.01 | U27: 0.01 | V27: 0.01 | W27: 0.01 | X27: 0.02
B28: Financial Markets Efficiency Index | C28: 0 | D28: 0 | E28: 0 | F28: 0 | G28: 0 | H28: 0 | I28: 0 | J28: 0 | K28: 0 | L28: 0 | M28: 0 | N28: 0 | O28: 0 | P28: 0 | Q28: 0 | R28: 0 | S28: 0 | T28: 0 | U28: 0 | V28: 0 | W28: 0 | X28: 0
B29: Financial Markets Index | C29: 0.01 | D29: 0.01 | E29: 0.01 | F29: 0.01 | G29: 0.01 | H29: 0.01 | I29: 0.01 | J29: 0.01 | K29: 0.01 | L29: 0.01 | M29: 0.01 | N29: 0.01 | O29: 0.01 | P29: 0.01 | Q29: 0.01 | R29: 0.01 | S29: 0.01 | T29: 0.01 | U29: 0.01 | V29: 0.01 | W29: 0.01 | X29: 0.01
A30: Cambodia | B30: Financial Development Index | C30: 0.06 | D30: 0.03 | E30: 0.07 | F30: 0.08 | G30: 0.07 | H30: 0.07 | I30: 0.09 | J30: 0.1 | K30: 0.1 | L30: 0.09 | M30: 0.1 | N30: 0.11 | O30: 0.12 | P30: 0.13 | Q30: 0.14 | R30: 0.15 | S30: 0.15 | T30: 0.16 | U30: 0.17 | V30: 0.18 | W30: 0.2 | X30: 0.21
B31: Financial Institutions Access Index | C31: 0 | D31: 0 | E31: 0 | F31: 0 | G31: 0 | H31: 0 | I31: 0.03 | J31: 0.04 | K31: 0.05 | L31: 0.07 | M31: 0.07 | N31: 0.08 | O31: 0.08 | P31: 0.09 | Q31: 0.11 | R31: 0.13 | S31: 0.15 | T31: 0.16 | U31: 0.18 | V31: 0.2 | W31: 0.25 | X31: 0.28
B32: Financial Institutions Depth Index | C32: 0.02 | D32: 0.02 | E32: 0.02 | F32: 0.02 | G32: 0.02 | H32: 0.02 | I32: 0.03 | J32: 0.04 | K32: 0.05 | L32: 0.05 | M32: 0.06 | N32: 0.06 | O32: 0.08 | P32: 0.11 | Q32: 0.13 | R32: 0.16 | S32: 0.18 | T32: 0.19 | U32: 0.22 | V32: 0.26 | W32: 0.28 | X32: 0.28
B33: Financial Institutions Efficiency Index | C33: 0.37 | D33: 0.17 | E33: 0.48 | F33: 0.51 | G33: 0.5 | H33: 0.47 | I33: 0.52 | J33: 0.56 | K33: 0.53 | L33: 0.47 | M33: 0.5 | N33: 0.53 | O33: 0.55 | P33: 0.56 | Q33: 0.57 | R33: 0.57 | S33: 0.57 | T33: 0.58 | U33: 0.56 | V33: 0.6 | W33: 0.59 | X33: 0.61
B34: Financial Institutions Index | C34: 0.11 | D34: 0.05 | E34: 0.14 | F34: 0.15 | G34: 0.15 | H34: 0.14 | I34: 0.17 | J34: 0.19 | K34: 0.19 | L34: 0.18 | M34: 0.19 | N34: 0.2 | O34: 0.22 | P34: 0.24 | Q34: 0.26 | R34: 0.28 | S34: 0.3 | T34: 0.31 | U34: 0.32 | V34: 0.36 | W34: 0.39 | X34: 0.41
B35: Financial Markets Access Index | C35: 0 | D35: 0 | E35: 0 | F35: 0 | G35: 0 | H35: 0 | I35: 0 | J35: 0 | K35: 0 | L35: 0 | M35: 0 | N35: 0 | O35: 0 | P35: 0 | Q35: 0 | R35: 0 | S35: 0 | T35: 0 | U35: 0 | V35: 0 | W35: 0 | X35: 0
B36: Financial Markets Depth Index | C36: 0 | D36: 0 | E36: 0 | F36: 0 | G36: 0 | H36: 0 | I36: 0 | J36: 0 | K36: 0.01 | L36: 0.01 | M36: 0.03 | N36: 0.04 | O36: 0.03 | P36: 0.03 | Q36: 0.02 | R36: 0.02 | S36: 0.02 | T36: 0.02 | U36: 0.01 | V36: 0 | W36: 0 | X36: 0
B37: Financial Markets Efficiency Index | C37: 0 | D37: 0 | E37: 0 | F37: 0 | G37: 0 | H37: 0 | I37: 0 | J37: 0 | K37: 0 | L37: 0 | M37: 0 | N37: 0 | O37: 0 | P37: 0 | Q37: 0 | R37: 0 | S37: 0 | T37: 0 | U37: 0 | V37: 0 | W37: 0 | X37: 0
B38: Financial Markets Index | C38: 0 | D38: 0 | E38: 0 | F38: 0 | G38: 0 | H38: 0 | I38: 0 | J38: 0 | K38: 0 | L38: 0 | M38: 0.01 | N38: 0.01 | O38: 0.01 | P38: 0.01 | Q38: 0.01 | R38: 0.01 | S38: 0.01 | T38: 0.01 | U38: 0 | V38: 0 | W38: 0 | X38: 0
A39: Cameroon | B39: Financial Development Index | C39: 0.08 | D39: 0.08 | E39: 0.08 | F39: 0.07 | G39: 0.07 | H39: 0.08 | I39: 0.08 | J39: 0.09 | K39: 0.09 | L39: 0.08 | M39: 0.08 | N39: 0.08 | O39: 0.08 | P39: 0.1 | Q39: 0.08 | R39: 0.08 | S39: 0.08 | T39: 0.09 | U39: 0.09 | V39: 0.09 | W39: 0.09 | X39: 0.1
B40: Financial Institutions Access Index | C40: 0.01 | D40: 0.01 | E40: 0.01 | F40: 0.01 | G40: 0.01 | H40: 0.01 | I40: 0.02 | J40: 0.02 | K40: 0.02 | L40: 0.02 | M40: 0.03 | N40: 0.03 | O40: 0.03 | P40: 0.04 | Q40: 0.04 | R40: 0.04 | S40: 0.04 | T40: 0.04 | U40: 0.05 | V40: 0.05 | W40: 0.05 | X40: 0.05
...

Sheet INST
A1: Country | B1: 2000 [YR2000] | C1: 2001 [YR2001] | D1: 2002 [YR2002] | E1: 2003 [YR2003] | F1: 2004 [YR2004] | G1: 2005 [YR2005] | H1: 2006 [YR2006] | I1: 2007 [YR2007] | J1: 2008 [YR2008] | K1: 2009 [YR2009] | L1: 2010 [YR2010] | M1: 2011 [YR2011] | N1: 2012 [YR2012] | O1: 2013 [YR2013] | P1: 2014 [YR2014] | Q1: 2015 [YR2015] | R1: 2016 [YR2016] | S1: 2017 [YR2017] | T1: 2018 [YR2018] | U1: 2019 [YR2019] | V1: 2020 [YR2020] | W1: 2021 [YR2021] | Z1: Average
A2: Angola | B2: 0.38 | C2: 0.36 | D2: 0.46 | E2: 0.48 | F2: 0.46 | G2: 0.46 | H2: 0.47 | I2: 0.48 | J2: 0.49 | K2: 0.49 | L2: 0.48 | M2: 0.46 | N2: 0.45 | O2: 0.46 | P2: 0.43 | Q2: 0.41 | R2: 0.42 | S2: 0.41 | T2: 0.45 | U2: 0.49 | V2: 0.47 | W2: 0.49 | Z2: =AVERAGE(B2:W2) -> 0.45227273
A3: Bangladesh | B3: 0.55 | C3: 0.5 | D3: 0.4 | E3: 0.4 | F3: 0.42 | G3: 0.47 | H3: 0.45 | I3: 0.47 | J3: 0.46 | K3: 0.52 | L3: 0.49 | M3: 0.47 | N3: 0.47 | O3: 0.47 | P3: 0.48 | Q3: 0.5 | R3: 0.49 | S3: 0.48 | T3: 0.48 | U3: 0.49 | V3: 0.49 | W3: 0.51 | Z3: =AVERAGE(B3:W3) -> 0.47545455
A4: Bolivia | B4: 0.6 | C4: 0.61 | D4: 0.56 | E4: 0.57 | F4: 0.52 | G4: 0.5 | H4: 0.48 | I4: 0.47 | J4: 0.51 | K4: 0.48 | L4: 0.47 | M4: 0.47 | N4: 0.45 | O4: 0.49 | P4: 0.52 | Q4: 0.51 | R4: 0.5 | S4: 0.51 | T4: 0.5 | U4: 0.49 | V4: 0.48 | W4: 0.47 | Z4: =AVERAGE(B4:W4) -> 0.50727273
A5: Cameroon | B5: 0.48 | C5: 0.45 | D5: 0.43 | E5: 0.42 | F5: 0.47 | G5: 0.49 | H5: 0.54 | I5: 0.55 | J5: 0.57 | K5: 0.55 | L5: 0.52 | M5: 0.48 | N5: 0.47 | O5: 0.47 | P5: 0.45 | Q5: 0.45 | R5: 0.45 | S5: 0.41 | T5: 0.42 | U5: 0.41 | V5: 0.42 | W5: 0.41 | Z5: =AVERAGE(B5:W5) -> 0.46863636
A6: Congo, Rep. | B6: 0.35 | C6: 0.42 | D6: 0.43 | E6: 0.42 | F6: 0.43 | G6: 0.43 | H6: 0.44 | I6: 0.44 | J6: 0.44 | K6: 0.43 | L6: 0.43 | M6: 0.43 | N6: 0.42 | O6: 0.42 | P6: 0.42 | Q6: 0.46 | R6: 0.43 | S6: 0.39 | T6: 0.4 | U6: 0.43 | V6: 0.41 | W6: 0.42 | Z6: =AVERAGE(B6:W6) -> 0.42227273
A7: Côte d'Ivoire | B7: 0.56 | C7: 0.34 | D7: 0.35 | E7: 0.37 | F7: 0.32 | G7: 0.29 | H7: 0.31 | I7: 0.33 | J7: 0.34 | K7: 0.34 | L7: 0.34 | M7: 0.37 | N7: 0.37 | O7: 0.37 | P7: 0.39 | Q7: 0.39 | R7: 0.41 | S7: 0.41 | T7: 0.41 | U7: 0.41 | V7: 0.39 | W7: 0.43 | Z7: =AVERAGE(B7:W7) -> 0.37454545
A8: Egypt, Arab Rep. | B8: 0.58 | C8: 0.59 | D8: 0.53 | E8: 0.54 | F8: 0.53 | G8: 0.54 | H8: 0.54 | I8: 0.52 | J8: 0.52 | K8: 0.51 | L8: 0.49 | M8: 0.45 | N8: 0.44 | O8: 0.44 | P8: 0.46 | Q8: 0.47 | R8: 0.47 | S8: 0.5 | T8: 0.5 | U8: 0.53 | V8: 0.51 | W8: 0.52 | Z8: =AVERAGE(B8:W8) -> 0.50818182
A9: Ghana | B9: 0.54 | C9: 0.5 | D9: 0.49 | E9: 0.49 | F9: 0.52 | G9: 0.55 | H9: 0.57 | I9: 0.56 | J9: 0.56 | K9: 0.56 | L9: 0.56 | M9: 0.58 | N9: 0.57 | O9: 0.57 | P9: 0.58 | Q9: 0.6 | R9: 0.59 | S9: 0.58 | T9: 0.59 | U9: 0.58 | V9: 0.59 | W9: 0.57 | Z9: =AVERAGE(B9:W9) -> 0.55909091
A10: Haiti | B10: 0.32 | C10: 0.34 | D10: 0.3 | E10: 0.29 | F10: 0.3 | G10: 0.25 | H10: 0.23 | I10: 0.29 | J10: 0.26 | K10: 0.27 | L10: 0.25 | M10: 0.27 | N10: 0.28 | O10: 0.27 | P10: 0.28 | Q10: 0.27 | R10: 0.28 | S10: 0.33 | T10: 0.32 | U10: 0.31 | V10: 0.3 | W10: 0.28 | Z10: =AVERAGE(B10:W10) -> 0.28590909
A11: Honduras | B11: 0.52 | C11: 0.53 | D11: 0.53 | E11: 0.53 | F11: 0.51 | G11: 0.51 | H11: 0.51 | I11: 0.5 | J11: 0.49 | K11: 0.49 | L11: 0.5 | M11: 0.51 | N11: 0.48 | O11: 0.49 | P11: 0.5 | Q11: 0.52 | R11: 0.52 | S11: 0.51 | T11: 0.54 | U11: 0.51 | V11: 0.53 | W11: 0.52 | Z11: =AVERAGE(B11:W11) -> 0.51136364
A12: India | B12: 0.62 | C12: 0.59 | D12: 0.62 | E12: 0.63 | F12: 0.67 | G12: 0.67 | H12: 0.66 | I12: 0.65 | J12: 0.65 | K12: 0.66 | L12: 0.65 | M12: 0.63 | N12: 0.63 | O12: 0.63 | P12: 0.64 | Q12: 0.67 | R12: 0.67 | S12: 0.67 | T12: 0.65 | U12: 0.67 | V12: 0.67 | W12: 0.68 | Z12: =AVERAGE(B12:W12) -> 0.64909091
A13: Jordan | B13: 0.71 | C13: 0.67 | D13: 0.66 | E13: 0.67 | F13: 0.68 | G13: 0.68 | H13: 0.69 | I13: 0.67 | J13: 0.66 | K13: 0.66 | L13: 0.65 | M13: 0.63 | N13: 0.59 | O13: 0.6 | P13: 0.61 | Q13: 0.61 | R13: 0.59 | S13: 0.57 | T13: 0.56 | U13: 0.57 | V13: 0.57 | W13: 0.55 | Z13: =AVERAGE(B13:W13) -> 0.62954545
... A28: Zambia | B28: 0.65 | C28: 0.6 | D28: 0.51 | E28: 0.52 | F28: 0.57 | G28: 0.59 | H28: 0.57 | I28: 0.58 | J28: 0.57 | K28: 0.57 | L28: 0.57 | M28: 0.56 | N28: 0.55 | O28: 0.55 | P28: 0.55 | Q28: 0.56 | R28: 0.57 | S28: 0.55 | T28: 0.54 | U28: 0.54 | V28: 0.53 | W28: 0.56 | Z28: =AVERAGE(B28:W28) -> 0.56181818
A32: 1
A33: 2
A34: 3
A35: 4
A36: 5
A37: 6

Sheet INST all indicators
A1: code | B1: country | C1: INST21 | D1: PRS21VA | E1: PRS21PV | F1: PRS21GE | G1: PRS21RQ | H1: PRS21RL | I1: PRS21CC | J1: INST20 | K1: PRS20VA | L1: PRS20PV | M1: PRS20GE | N1: PRS20RQ | O1: PRS20RL | P1: PRS20CC | Q1: INST19 | R1: PRS19VA | S1: PRS19PV | T1: PRS19GE | U1: PRS19RQ | V1: PRS19RL | W1: PRS19CC | X1: INST18 | Y1: PRS18VA | Z1: PRS18PV | AA1: PRS18GE | AB1: PRS18RQ | AC1: PRS18RL | AD1: PRS18CC | AE1: INST17 | AF1: PRS17VA | AG1: PRS17PV | AH1: PRS17GE | AI1: PRS17RQ | AJ1: PRS17RL | AK1: PRS17CC | AL1: INST16 | AM1: PRS16VA | AN1: PRS16PV | AO1: PRS16GE | AP1: PRS16RQ | AQ1: PRS16RL | AR1: PRS16CC | AS1: INST15 | AT1: PRS15VA | AU1: PRS15PV | AV1: PRS15GE | AW1: PRS15RQ | AX1: PRS15RL | AY1: PRS15CC | AZ1: INST14 | BA1: PRS14VA | BB1: PRS14PV | BC1: PRS14GE | BD1: PRS14RQ | BE1: PRS14RL | BF1: PRS14CC | BG1: INST13 | BH1: PRS13VA | BI1: PRS13PV | BJ1: PRS13GE | BK1: PRS13RQ | BL1: PRS13RL | BM1: PRS13CC | BN1: INST12 | BO1: PRS12VA | BP1: PRS12PV | BQ1: PRS12GE | BR1: PRS12RQ | BS1: PRS12RL | BT1: PRS12CC | BU1: INST11 | BV1: PRS11VA | BW1: PRS11PV | BX1: PRS11GE | BY1: PRS11RQ | BZ1: PRS11RL | CA1: PRS11CC | CB1: INST10 | CC1: PRS10VA | CD1: PRS10PV | CE1: PRS10GE | CF1: PRS10RQ | CG1: PRS10RL | CH1: PRS10CC | CI1: INST09 | CJ1: PRS09VA | CK1: PRS09PV | CL1: PRS09GE | CM1: PRS09RQ | CN1: PRS09RL | CO1: PRS09CC | CP1: INST08 | CQ1: PRS08VA | CR1: PRS08PV | CS1: PRS08GE | CT1: PRS08RQ | CU1: PRS08RL | CV1: PRS08CC | CW1: INST07 | CX1: PRS07VA | CY1: PRS07PV | CZ1: PRS07GE | DA1: PRS07RQ | DB1: PRS07RL | DC1: PRS07CC | DD1: INST06 | DE1: PRS06VA | DF1: PRS06PV | DG1: PRS06GE | DH1: PRS06RQ | DI1: PRS06RL | DJ1: PRS06CC | DK1: INST05 | DL1: PRS05VA | DM1: PRS05PV | DN1: PRS05GE | DO1: PRS05RQ | DP1: PRS05RL | DQ1: PRS05CC | DR1: INST04 | DS1: PRS04VA | DT1: PRS04PV | DU1: PRS04GE | DV1: PRS04RQ | DW1: PRS04RL | DX1: PRS04CC | DY1: INST03 | DZ1: PRS03VA | EA1: PRS03PV | EB1: PRS03GE | EC1: PRS03RQ | ED1: PRS03RL | EE1: PRS03CC | EF1: INST02 | EG1: PRS02VA | EH1: PRS02PV | EI1: PRS02GE | EJ1: PRS02RQ | EK1: PRS02RL | EL1: PRS02CC | EM1: INST01 | EN1: PRS01VA | EO1: PRS01PV | EP1: PRS01GE | EQ1: PRS01RQ | ER1: PRS01RL | ES1: PRS01CC | ET1: INST00 | EU1: PRS00VA | EV1: PRS00PV | EW1: PRS00GE | EX1: PRS00RQ | EY1: PRS00RL | EZ1: PRS00CC
A2: AGO | B2: Angola | C2: 0.49 | D2: 0.46 | E2: 0.66 | F2: 0.38 | G2: 0.68 | H2: 0.42 | I2: 0.33 | J2: 0.47 | K2: 0.46 | L2: 0.65 | M2: 0.38 | N2: 0.59 | O2: 0.42 | P2: 0.33 | Q2: 0.49 | R2: 0.38 | S2: 0.66 | T2: 0.38 | U2: 0.68 | V2: 0.42 | W2: 0.42 | X2: 0.45 | Y2: 0.38 | Z2: 0.67 | AA2: 0.38 | AB2: 0.64 | AC2: 0.42 | AD2: 0.25 | AE2: 0.41 | AF2: 0.38 | AG2: 0.65 | AH2: 0.38 | AI2: 0.45 | AJ2: 0.42 | AK2: 0.17 | AL2: 0.42 | AM2: 0.38 | AN2: 0.66 | AO2: 0.38 | AP2: 0.5 | AQ2: 0.42 | AR2: 0.17 | AS2: 0.41 | AT2: 0.38 | AU2: 0.65 | AV2: 0.38 | AW2: 0.5 | AX2: 0.42 | AY2: 0.17 | AZ2: 0.43 | BA2: 0.38 | BB2: 0.65 | BC2: 0.38 | BD2: 0.59 | BE2: 0.42 | BF2: 0.17 | BG2: 0.46 | BH2: 0.38 | BI2: 0.68 | BJ2: 0.38 | BK2: 0.64 | BL2: 0.42 | BM2: 0.25 | BN2: 0.45 | BO2: 0.38 | BP2: 0.69 | BQ2: 0.38 | BR2: 0.59 | BS2: 0.42 | BT2: 0.25 | BU2: 0.46 | BV2: 0.38 | BW2: 0.67 | BX2: 0.38 | BY2: 0.59 | BZ2: 0.42 | CA2: 0.33 | CB2: 0.48 | CC2: 0.33 | CD2: 0.73 | CE2: 0.38 | CF2: 0.64 | CG2: 0.5 | CH2: 0.33 | CI2: 0.49 | CJ2: 0.33 | CK2: 0.75 | CL2: 0.38 | CM2: 0.64 | CN2: 0.5 | CO2: 0.33 | CP2: 0.49 | CQ2: 0.33 | CR2: 0.75 | CS2: 0.38 | CT2: 0.64 | CU2: 0.5 | CV2: 0.33 | CW2: 0.48 | CX2: 0.33 | CY2: 0.73 | CZ2: 0.38 | DA2: 0.64 | DB2: 0.5 | DC2: 0.33 | DD2: 0.47 | DE2: 0.33 | DF2: 0.74 | DG2: 0.25 | DH2: 0.64 | DI2: 0.5 | DJ2: 0.33 | DK2: 0.46 | DL2: 0.33 | DM2: 0.73 | DN2: 0.25 | DO2: 0.59 | DP2: 0.5 | DQ2: 0.33 | DR2: 0.46 | DS2: 0.33 | DT2: 0.72 | DU2: 0.25 | DV2: 0.64 | DW2: 0.5 | DX2: 0.33 | DY2: 0.48 | DZ2: 0.42 | EA2: 0.74 | EB2: 0.25 | EC2: 0.64 | ED2: 0.5 | EE2: 0.33 | EF2: 0.46 | EG2: 0.33 | EH2: 0.67 | EI2: 0.25 | EJ2: 0.68 | EK2: 0.5 | EL2: 0.33 | EM2: 0.36 | EN2: 0.33 | EO2: 0.65 | EP2: 0.25 | EQ2: 0.09 | ER2: 0.5 | ES2: 0.33 | ET2: 0.38 | EU2: 0.42 | EV2: 0.51 | EW2: 0.25 | EX2: 0.27 | EY2: 0.5 | EZ2: 0.33
A3: BGD | B3: Bangladesh | C3: 0.51 | D3: 0.54 | E3: 0.57 | F3: 0.63 | G3: 0.55 | H3: 0.33 | I3: 0.42 | J3: 0.49 | K3: 0.54 | L3: 0.58 | M3: 0.5 | N3: 0.59 | O3: 0.33 | P3: 0.42 | Q3: 0.49 | R3: 0.54 | S3: 0.6 | T3: 0.5 | U3: 0.55 | V3: 0.33 | W3: 0.42 | X3: 0.48 | Y3: 0.54 | Z3: 0.55 | AA3: 0.5 | AB3: 0.55 | AC3: 0.33 | AD3: 0.42 | AE3: 0.48 | AF3: 0.54 | AG3: 0.56 | AH3: 0.5 | AI3: 0.55 | AJ3: 0.33 | AK3: 0.42 | AL3: 0.49 | AM3: 0.5 | AN3: 0.58 | AO3: 0.5 | AP3: 0.5 | AQ3: 0.33 | AR3: 0.5 | AS3: 0.5 | AT3: 0.5 | AU3: 0.58 | AV3: 0.5 | AW3: 0.59 | AX3: 0.33 | AY3: 0.5 | AZ3: 0.48 | BA3: 0.5 | BB3: 0.56 | BC3: 0.5 | BD3: 0.5 | BE3: 0.33 | BF3: 0.5 | BG3: 0.47 | BH3: 0.5 | BI3: 0.52 | BJ3: 0.5 | BK3: 0.45 | BL3: 0.33 | BM3: 0.5 | BN3: 0.47 | BO3: 0.5 | BP3: 0.55 | BQ3: 0.5 | BR3: 0.45 | BS3: 0.33 | BT3: 0.5 | BU3: 0.47 | BV3: 0.5 | BW3: 0.55 | BX3: 0.5 | BY3: 0.45 | BZ3: 0.33 | CA3: 0.5 | CB3: 0.49 | CC3: 0.5 | CD3: 0.58 | CE3: 0.5 | CF3: 0.55 | CG3: 0.33 | CH3: 0.5 | CI3: 0.52 | CJ3: 0.54 | CK3: 0.62 | CL3: 0.5 | CM3: 0.55 | CN3: 0.42 | CO3: 0.5 | CP3: 0.46 | CQ3: 0.33 | CR3: 0.57 | CS3: 0.5 | CT3: 0.55 | CU3: 0.42 | CV3: 0.42 | CW3: 0.47 | CX3: 0.38 | CY3: 0.55 | CZ3: 0.5 | DA3: 0.55 | DB3: 0.42 | DC3: 0.42 | DD3: 0.45 | DE3: 0.46 | DF3: 0.56 | DG3: 0.5 | DH3: 0.5 | DI3: 0.42 | DJ3: 0.25 | DK3: 0.47 | DL3: 0.5 | DM3: 0.59 | DN3: 0.5 | DO3: 0.55 | DP3: 0.42 | DQ3: 0.25 | DR3: 0.42 | DS3: 0.46 | DT3: 0.58 | DU3: 0.5 | DV3: 0.5 | DW3: 0.25 | DX3: 0.25 | DY3: 0.4 | DZ3: 0.42 | EA3: 0.63 | EB3: 0.5 | EC3: 0.5 | ED3: 0.17 | EE3: 0.17 | EF3: 0.4 | EG3: 0.46 | EH3: 0.68 | EI3: 0.5 | EJ3: 0.36 | EK3: 0.25 | EL3: 0.17 | EM3: 0.5 | EN3: 0.67 | EO3: 0.73 | EP3: 0.5 | EQ3: 0.45 | ER3: 0.33 | ES3: 0.33 | ET3: 0.55 | EU3: 0.67 | EV3: 0.82 | EW3: 0.5 | EX3: 0.45 | EY3: 0.5 | EZ3: 0.33
A4: BOL | B4: Bolivia | C4: 0.47 | D4: 0.46 | E4: 0.63 | F4: 0.63 | G4: 0.5 | H4: 0.33 | I4: 0.25 | J4: 0.48 | K4: 0.46 | L4: 0.66 | M4: 0.63 | N4: 0.5 | O4: 0.33 | P4: 0.33 | Q4: 0.49 | R4: 0.46 | S4: 0.6 | T4: 0.63 | U4: 0.5 | V4: 0.42 | W4: 0.33 | X4: 0.5 | Y4: 0.54 | Z4: 0.59 | AA4: 0.63 | AB4: 0.5 | AC4: 0.42 | AD4: 0.33 | AE4: 0.51 | AF4: 0.54 | AG4: 0.61 | AH4: 0.63 | AI4: 0.5 | AJ4: 0.42 | AK4: 0.33 | AL4: 0.5 | AM4: 0.54 | AN4: 0.61 | AO4: 0.63 | AP4: 0.45 | AQ4: 0.42 | AR4: 0.33 | AS4: 0.51 | AT4: 0.54 | AU4: 0.65 | AV4: 0.63 | AW4: 0.5 | AX4: 0.42 | AY4: 0.33 | AZ4: 0.52 | BA4: 0.54 | BB4: 0.7 | BC4: 0.63 | BD4: 0.5 | BE4: 0.42 | BF4: 0.33 | BG4: 0.49 | BH4: 0.54 | BI4: 0.65 | BJ4: 0.63 | BK4: 0.36 | BL4: 0.42 | BM4: 0.33 | BN4: 0.45 | BO4: 0.54 | BP4: 0.64 | BQ4: 0.5 | BR4: 0.36 | BS4: 0.42 | BT4: 0.25 | BU4: 0.47 | BV4: 0.54 | BW4: 0.64 | BX4: 0.5 | BY4: 0.36 | BZ4: 0.42 | CA4: 0.33 | CB4: 0.47 | CC4: 0.54 | CD4: 0.68 | CE4: 0.5 | CF4: 0.36 | CG4: 0.42 | CH4: 0.33 | CI4: 0.48 | CJ4: 0.58 | CK4: 0.7 | CL4: 0.5 | CM4: 0.36 | CN4: 0.42 | CO4: 0.33 | CP4: 0.51 | CQ4: 0.67 | CR4: 0.68 | CS4: 0.5 | CT4: 0.36 | CU4: 0.5 | CV4: 0.33 | CW4: 0.47 | CX4: 0.67 | CY4: 0.66 | CZ4: 0.5 | DA4: 0.18 | DB4: 0.5 | DC4: 0.33 | DD4: 0.48 | DE4: 0.75 | DF4: 0.6 | DG4: 0.5 | DH4: 0.18 | DI4: 0.5 | DJ4: 0.33 | DK4: 0.5 | DL4: 0.58 | DM4: 0.56 | DN4: 0.5 | DO4: 0.5 | DP4: 0.5 | DQ4: 0.33 | DR4: 0.52 | DS4: 0.58 | DT4: 0.61 | DU4: 0.5 | DV4: 0.59 | DW4: 0.5 | DX4: 0.33 | DY4: 0.57 | DZ4: 0.58 | EA4: 0.7 | EB4: 0.5 | EC4: 0.77 | ED4: 0.5 | EE4: 0.33 | EF4: 0.56 | EG4: 0.58 | EH4: 0.67 | EI4: 0.5 | EJ4: 0.77 | EK4: 0.5 | EL4: 0.33 | EM4: 0.61 | EN4: 0.58 | EO4: 0.76 | EP4: 0.5 | EQ4: 0.82 | ER4: 0.5 | ES4: 0.5 | ET4: 0.6 | EU4: 0.58 | EV4: 0.67 | EW4: 0.5 | EX4: 0.82 | EY4: 0.5 | EZ4: 0.5
A5: CMR | B5: Cameroon | C5: 0.41 | D5: 0.38 | E5: 0.56 | F5: 0.38 | G5: 0.55 | H5: 0.33 | I5: 0.25 | J5: 0.42 | K5: 0.38 | L5: 0.55 | M5: 0.38 | N5: 0.64 | O5: 0.33 | P5: 0.25 | Q5: 0.41 | R5: 0.38 | S5: 0.57 | T5: 0.38 | U5: 0.55 | V5: 0.33 | W5: 0.25 | X5: 0.42 | Y5: 0.42 | Z5: 0.58 | AA5: 0.38 | AB5: 0.55 | AC5: 0.33 | AD5: 0.25 | AE5: 0.41 | AF5: 0.42 | AG5: 0.57 | AH5: 0.38 | AI5: 0.55 | AJ5: 0.33 | AK5: 0.25 | AL5: 0.45 | AM5: 0.42 | AN5: 0.61 | AO5: 0.38 | AP5: 0.64 | AQ5: 0.33 | AR5: 0.33 | AS5: 0.45 | AT5: 0.42 | AU5: 0.63 | AV5: 0.38 | AW5: 0.64 | AX5: 0.33 | AY5: 0.33 | AZ5: 0.45 | BA5: 0.42 | BB5: 0.63 | BC5: 0.38 | BD5: 0.64 | BE5: 0.33 | BF5: 0.33 | BG5: 0.47 | BH5: 0.42 | BI5: 0.71 | BJ5: 0.38 | BK5: 0.64 | BL5: 0.33 | BM5: 0.33 | BN5: 0.47 | BO5: 0.46 | BP5: 0.7 | BQ5: 0.38 | BR5: 0.59 | BS5: 0.33 | BT5: 0.33 | BU5: 0.48 | BV5: 0.46 | BW5: 0.71 | BX5: 0.38 | BY5: 0.59 | BZ5: 0.33 | CA5: 0.42 | CB5: 0.52 | CC5: 0.5 | CD5: 0.75 | CE5: 0.38 | CF5: 0.73 | CG5: 0.33 | CH5: 0.42 | CI5: 0.55 | CJ5: 0.5 | CK5: 0.79 | CL5: 0.38 | CM5: 0.73 | CN5: 0.33 | CO5: 0.58 | CP5: 0.57 | CQ5: 0.54 | CR5: 0.79 | CS5: 0.38 | CT5: 0.73 | CU5: 0.33 | CV5: 0.67 | CW5: 0.55 | CX5: 0.63 | CY5: 0.79 | CZ5: 0.25 | DA5: 0.73 | DB5: 0.33 | DC5: 0.58 | DD5: 0.54 | DE5: 0.63 | DF5: 0.78 | DG5: 0.25 | DH5: 0.68 | DI5: 0.42 | DJ5: 0.5 | DK5: 0.49 | DL5: 0.63 | DM5: 0.79 | DN5: 0.25 | DO5: 0.64 | DP5: 0.33 | DQ5: 0.33 | DR5: 0.47 | DS5: 0.63 | DT5: 0.64 | DU5: 0.25 | DV5: 0.64 | DW5: 0.33 | DX5: 0.33 | DY5: 0.42 | DZ5: 0.5 | EA5: 0.63 | EB5: 0.25 | EC5: 0.5 | ED5: 0.33 | EE5: 0.33 | EF5: 0.43 | EG5: 0.5 | EH5: 0.65 | EI5: 0.25 | EJ5: 0.5 | EK5: 0.33 | EL5: 0.33 | EM5: 0.45 | EN5: 0.5 | EO5: 0.63 | EP5: 0.25 | EQ5: 0.64 | ER5: 0.33 | ES5: 0.33 | ET5: 0.48 | EU5: 0.5 | EV5: 0.65 | EW5: 0.25 | EX5: 0.64 | EY5: 0.5 | EZ5: 0.33
A6: COG | B6: Congo, Rep. | C6: 0.42 | D6: 0.46 | E6: 0.75 | F6: 0.25 | G6: 0.59 | H6: 0.33 | I6: 0.17 | J6: 0.41 | K6: 0.46 | L6: 0.73 | M6: 0.25 | N6: 0.5 | O6: 0.33 | P6: 0.17 | Q6: 0.43 | R6: 0.46 | S6: 0.72 | T6: 0.25 | U6: 0.64 | V6: 0.33 | W6: 0.17 | X6: 0.4 | Y6: 0.46 | Z6: 0.71 | AA6: 0.25 | AB6: 0.5 | AC6: 0.33 | AD6: 0.17 | AE6: 0.39 | AF6: 0.46 | AG6: 0.7 | AH6: 0.25 | AI6: 0.45 | AJ6: 0.33 | AK6: 0.17 | AL6: 0.43 | AM6: 0.5 | AN6: 0.7 | AO6: 0.25 | AP6: 0.55 | AQ6: 0.33 | AR6: 0.25 | AS6: 0.46 | AT6: 0.5 | AU6: 0.73 | AV6: 0.25 | AW6: 0.68 | AX6: 0.33 | AY6: 0.25 | AZ6: 0.42 | BA6: 0.25 | BB6: 0.73 | BC6: 0.25 | BD6: 0.68 | BE6: 0.33 | BF6: 0.25 | BG6: 0.42 | BH6: 0.25 | BI6: 0.73 | BJ6: 0.25 | BK6: 0.68 | BL6: 0.33 | BM6: 0.25 | BN6: 0.42 | BO6: 0.25 | BP6: 0.73 | BQ6: 0.25 | BR6: 0.68 | BS6: 0.33 | BT6: 0.25 | BU6: 0.43 | BV6: 0.25 | BW6: 0.72 | BX6: 0.25 | BY6: 0.68 | BZ6: 0.33 | CA6: 0.33 | CB6: 0.43 | CC6: 0.25 | CD6: 0.76 | CE6: 0.25 | CF6: 0.68 | CG6: 0.33 | CH6: 0.33 | CI6: 0.43 | CJ6: 0.25 | CK6: 0.76 | CL6: 0.25 | CM6: 0.68 | CN6: 0.33 | CO6: 0.33 | CP6: 0.44 | CQ6: 0.25 | CR6: 0.76 | CS6: 0.25 | CT6: 0.73 | CU6: 0.33 | CV6: 0.33 | CW6: 0.44 | CX6: 0.25 | CY6: 0.73 | CZ6: 0.25 | DA6: 0.73 | DB6: 0.33 | DC6: 0.33 | DD6: 0.44 | DE6: 0.25 | DF6: 0.76 | DG6: 0.25 | DH6: 0.73 | DI6: 0.33 | DJ6: 0.33 | DK6: 0.43 | DL6: 0.25 | DM6: 0.76 | DN6: 0.25 | DO6: 0.68 | DP6: 0.33 | DQ6: 0.33 | DR6: 0.43 | DS6: 0.25 | DT6: 0.8 | DU6: 0.25 | DV6: 0.59 | DW6: 0.33 | DX6: 0.33 | DY6: 0.42 | DZ6: 0.25 | EA6: 0.79 | EB6: 0.25 | EC6: 0.59 | ED6: 0.33 | EE6: 0.33 | EF6: 0.43 | EG6: 0.25 | EH6: 0.76 | EI6: 0.25 | EJ6: 0.68 | EK6: 0.33 | EL6: 0.33 | EM6: 0.42 | EN6: 0.08 | EO6: 0.76 | EP6: 0.25 | EQ6: 0.45 | ER6: 0.33 | ES6: 0.67 | ET6: 0.35 | EU6: 0.08 | EV6: 0.67 | EW6: 0.25 | EX6: 0.27 | EY6: 0.17 | EZ6: 0.67
A7: CIV | B7: Côte d'Ivoire | C7: 0.43 | D7: 0.54 | E7: 0.62 | F7: 0 | G7: 0.59 | H7: 0.42 | I7: 0.42 | J7: 0.39 | K7: 0.5 | L7: 0.57 | M7: 0 | N7: 0.55 | O7: 0.42 | P7: 0.33 | Q7: 0.41 | R7: 0.54 | S7: 0.55 | T7: 0 | U7: 0.64 | V7: 0.42 | W7: 0.33 | X7: 0.41 | Y7: 0.58 | Z7: 0.54 | AA7: 0 | AB7: 0.59 | AC7: 0.42 | AD7: 0.33 | AE7: 0.41 | AF7: 0.54 | AG7: 0.56 | AH7: 0 | AI7: 0.59 | AJ7: 0.42 | AK7: 0.33 | AL7: 0.41 | AM7: 0.5 | AN7: 0.57 | AO7: 0 | AP7: 0.64 | AQ7: 0.42 | AR7: 0.33 | AS7: 0.39 | AT7: 0.38 | AU7: 0.59 | AV7: 0 | AW7: 0.64 | AX7: 0.42 | AY7: 0.33 | AZ7: 0.39 | BA7: 0.38 | BB7: 0.59 | BC7: 0 | BD7: 0.64 | BE7: 0.42 | BF7: 0.33 | BG7: 0.37 | BH7: 0.38 | BI7: 0.56 | BJ7: 0 | BK7: 0.59 | BL7: 0.42 | BM7: 0.25 | BN7: 0.37 | BO7: 0.38 | BP7: 0.52 | BQ7: 0 | BR7: 0.64 | BS7: 0.42 | BT7: 0.25 | BU7: 0.37 | BV7: 0.38 | BW7: 0.59 | BX7: 0 | BY7: 0.5 | BZ7: 0.42 | CA7: 0.33 | CB7: 0.34 | CC7: 0.38 | CD7: 0.54 | CE7: 0 | CF7: 0.36 | CG7: 0.42 | CH7: 0.33 | CI7: 0.34 | CJ7: 0.29 | CK7: 0.55 | CL7: 0 | CM7: 0.36 | CN7: 0.42 | CO7: 0.42 | CP7: 0.34 | CQ7: 0.29 | CR7: 0.57 | CS7: 0 | CT7: 0.36 | CU7: 0.42 | CV7: 0.42 | CW7: 0.33 | CX7: 0.29 | CY7: 0.58 | CZ7: 0 | DA7: 0.36 | DB7: 0.42 | DC7: 0.33 | DD7: 0.31 | DE7: 0.29 | DF7: 0.56 | DG7: 0 | DH7: 0.36 | DI7: 0.42 | DJ7: 0.25 | DK7: 0.29 | DL7: 0.25 | DM7: 0.47 | DN7: 0 | DO7: 0.36 | DP7: 0.42 | DQ7: 0.25 | DR7: 0.32 | DS7: 0.25 | DT7: 0.53 | DU7: 0 | DV7: 0.41 | DW7: 0.42 | DX7: 0.33 | DY7: 0.37 | DZ7: 0.25 | EA7: 0.59 | EB7: 0 | EC7: 0.45 | ED7: 0.42 | EE7: 0.5 | EF7: 0.35 | EG7: 0.21 | EH7: 0.49 | EI7: 0 | EJ7: 0.45 | EK7: 0.42 | EL7: 0.5 | EM7: 0.34 | EN7: 0.33 | EO7: 0.61 | EP7: 0 | EQ7: 0.09 | ER7: 0.5 | ES7: 0.5 | ET7: 0.56 | EU7: 0.58 | EV7: 0.69 | EW7: 0.5 | EX7: 0.73 | EY7: 0.5 | EZ7: 0.33
A8: EGY | B8: Egypt, Arab Rep. | C8: 0.52 | D8: 0.25 | E8: 0.7 | F8: 0.63 | G8: 0.73 | H8: 0.5 | I8: 0.33 | J8: 0.51 | K8: 0.25 | L8: 0.7 | M8: 0.63 | N8: 0.68 | O8: 0.5 | P8: 0.33 | Q8: 0.53 | R8: 0.29 | S8: 0.74 | T8: 0.63 | U8: 0.68 | V8: 0.5 | W8: 0.33 | X8: 0.5 | Y8: 0.29 | Z8: 0.73 | AA8: 0.5 | AB8: 0.64 | AC8: 0.5 | AD8: 0.33 | AE8: 0.5 | AF8: 0.33 | AG8: 0.71 | AH8: 0.5 | AI8: 0.64 | AJ8: 0.5 | AK8: 0.33 | AL8: 0.47 | AM8: 0.25 | AN8: 0.66 | AO8: 0.5 | AP8: 0.59 | AQ8: 0.5 | AR8: 0.33 | AS8: 0.47 | AT8: 0.25 | AU8: 0.66 | AV8: 0.5 | AW8: 0.55 | AX8: 0.5 | AY8: 0.33 | AZ8: 0.46 | BA8: 0.25 | BB8: 0.65 | BC8: 0.5 | BD8: 0.5 | BE8: 0.5 | BF8: 0.33 | BG8: 0.44 | BH8: 0.25 | BI8: 0.59 | BJ8: 0.5 | BK8: 0.45 | BL8: 0.5 | BM8: 0.33 | BN8: 0.44 | BO8: 0.21 | BP8: 0.63 | BQ8: 0.5 | BR8: 0.45 | BS8: 0.5 | BT8: 0.33 | BU8: 0.45 | BV8: 0.25 | BW8: 0.64 | BX8: 0.5 | BY8: 0.45 | BZ8: 0.5 | CA8: 0.33 | CB8: 0.49 | CC8: 0.33 | CD8: 0.72 | CE8: 0.5 | CF8: 0.5 | CG8: 0.58 | CH8: 0.33 | CI8: 0.51 | CJ8: 0.42 | CK8: 0.75 | CL8: 0.5 | CM8: 0.5 | CN8: 0.58 | CO8: 0.33 | CP8: 0.52 | CQ8: 0.42 | CR8: 0.77 | CS8: 0.5 | CT8: 0.5 | CU8: 0.58 | CV8: 0.33 | CW8: 0.52 | CX8: 0.42 | CY8: 0.79 | CZ8: 0.5 | DA8: 0.5 | DB8: 0.58 | DC8: 0.33 | DD8: 0.54 | DE8: 0.42 | DF8: 0.84 | DG8: 0.5 | DH8: 0.5 | DI8: 0.67 | DJ8: 0.33 | DK8: 0.54 | DL8: 0.46 | DM8: 0.84 | DN8: 0.5 | DO8: 0.5 | DP8: 0.67 | DQ8: 0.25 | DR8: 0.53 | DS8: 0.42 | DT8: 0.86 | DU8: 0.5 | DV8: 0.5 | DW8: 0.67 | DX8: 0.25 | DY8: 0.54 | DZ8: 0.42 | EA8: 0.89 | EB8: 0.5 | EC8: 0.5 | ED8: 0.67 | EE8: 0.25 | EF8: 0.53 | EG8: 0.42 | EH8: 0.86 | EI8: 0.5 | EJ8: 0.5 | EK8: 0.67 | EL8: 0.25 | EM8: 0.59 | EN8: 0.42 | EO8: 0.8 | EP8: 0.5 | EQ8: 0.82 | ER8: 0.67 | ES8: 0.33 | ET8: 0.58 | EU8: 0.42 | EV8: 0.82 | EW8: 0.5 | EX8: 0.73 | EY8: 0.67 | EZ8: 0.33
A9: GHA | B9: Ghana | C9: 0.57 | D9: 0.67 | E9: 0.68 | F9: 0.63 | G9: 0.55 | H9: 0.42 | I9: 0.5 | J9: 0.59 | K9: 0.67 | L9: 0.7 | M9: 0.63 | N9: 0.64 | O9: 0.42 | P9: 0.5 | Q9: 0.58 | R9: 0.67 | S9: 0.68 | T9: 0.63 | U9: 0.59 | V9: 0.42 | W9: 0.5 | X9: 0.59 | Y9: 0.67 | Z9: 0.69 | AA9: 0.63 | AB9: 0.64 | AC9: 0.42 | AD9: 0.5 | AE9: 0.58 | AF9: 0.67 | AG9: 0.69 | AH9: 0.63 | AI9: 0.64 | AJ9: 0.42 | AK9: 0.42 | AL9: 0.59 | AM9: 0.67 | AN9: 0.7 | AO9: 0.63 | AP9: 0.64 | AQ9: 0.42 | AR9: 0.5 | AS9: 0.6 | AT9: 0.67 | AU9: 0.68 | AV9: 0.63 | AW9: 0.68 | AX9: 0.42 | AY9: 0.5 | AZ9: 0.58 | BA9: 0.67 | BB9: 0.67 | BC9: 0.63 | BD9: 0.59 | BE9: 0.42 | BF9: 0.5 | BG9: 0.57 | BH9: 0.67 | BI9: 0.71 | BJ9: 0.63 | BK9: 0.59 | BL9: 0.42 | BM9: 0.42 | BN9: 0.57 | BO9: 0.67 | BP9: 0.73 | BQ9: 0.63 | BR9: 0.59 | BS9: 0.42 | BT9: 0.42 | BU9: 0.58 | BV9: 0.67 | BW9: 0.74 | BX9: 0.63 | BY9: 0.59 | BZ9: 0.42 | CA9: 0.42 | CB9: 0.56 | CC9: 0.67 | CD9: 0.69 | CE9: 0.63 | CF9: 0.55 | CG9: 0.42 | CH9: 0.42 | CI9: 0.56 | CJ9: 0.67 | CK9: 0.74 | CL9: 0.63 | CM9: 0.64 | CN9: 0.42 | CO9: 0.25 | CP9: 0.56 | CQ9: 0.67 | CR9: 0.74 | CS9: 0.63 | CT9: 0.68 | CU9: 0.42 | CV9: 0.25 | CW9: 0.56 | CX9: 0.67 | CY9: 0.75 | CZ9: 0.63 | DA9: 0.68 | DB9: 0.42 | DC9: 0.25 | DD9: 0.57 | DE9: 0.67 | DF9: 0.77 | DG9: 0.63 | DH9: 0.68 | DI9: 0.42 | DJ9: 0.25 | DK9: 0.55 | DL9: 0.67 | DM9: 0.77 | DN9: 0.5 | DO9: 0.68 | DP9: 0.42 | DQ9: 0.25 | DR9: 0.52 | DS9: 0.58 | DT9: 0.68 | DU9: 0.5 | DV9: 0.59 | DW9: 0.33 | DX9: 0.42 | DY9: 0.49 | DZ9: 0.46 | EA9: 0.68 | EB9: 0.5 | EC9: 0.55 | ED9: 0.33 | EE9: 0.42 | EF9: 0.49 | EG9: 0.46 | EH9: 0.69 | EI9: 0.5 | EJ9: 0.55 | EK9: 0.33 | EL9: 0.42 | EM9: 0.5 | EN9: 0.42 | EO9: 0.67 | EP9: 0.5 | EQ9: 0.73 | ER9: 0.33 | ES9: 0.33 | ET9: 0.54 | EU9: 0.42 | EV9: 0.74 | EW9: 0.5 | EX9: 0.73 | EY9: 0.5 | EZ9: 0.33
A10: HTI | B10: Haiti | C10: 0.28 | D10: 0.25 | E10: 0.66 | F10: 0 | G10: 0.36 | H10: 0.25 | I10: 0.17 | J10: 0.3 | K10: 0.29 | L10: 0.66 | M10: 0 | N10: 0.36 | O10: 0.25 | P10: 0.25 | Q10: 0.31 | R10: 0.33 | S10: 0.67 | T10: 0 | U10: 0.36 | V10: 0.25 | W10: 0.25 | X10: 0.32 | Y10: 0.38 | Z10: 0.7 | AA10: 0 | AB10: 0.36 | AC10: 0.25 | AD10: 0.25 | AE10: 0.33 | AF10: 0.38 | AG10: 0.72 | AH10: 0 | AI10: 0.36 | AJ10: 0.25 | AK10: 0.25 | AL10: 0.28 | AM10: 0.29 | AN10: 0.67 | AO10: 0 | AP10: 0.27 | AQ10: 0.25 | AR10: 0.17 | AS10: 0.27 | AT10: 0.29 | AU10: 0.65 | AV10: 0 | AW10: 0.27 | AX10: 0.25 | AY10: 0.17 | AZ10: 0.28 | BA10: 0.29 | BB10: 0.69 | BC10: 0 | BD10: 0.27 | BE10: 0.25 | BF10: 0.17 | BG10: 0.27 | BH10: 0.25 | BI10: 0.7 | BJ10: 0 | BK10: 0.27 | BL10: 0.25 | BM10: 0.17 | BN10: 0.28 | BO10: 0.29 | BP10: 0.72 | BQ10: 0 | BR10: 0.27 | BS10: 0.25 | BT10: 0.17 | BU10: 0.27 | BV10: 0.21 | BW10: 0.73 | BX10: 0 | BY10: 0.27 | BZ10: 0.25 | CA10: 0.17 | CB10: 0.25 | CC10: 0.21 | CD10: 0.62 | CE10: 0 | CF10: 0.27 | CG10: 0.25 | CH10: 0.17 | CI10: 0.27 | CJ10: 0.21 | CK10: 0.66 | CL10: 0 | CM10: 0.32 | CN10: 0.25 | CO10: 0.17 | CP10: 0.26 | CQ10: 0.21 | CR10: 0.64 | CS10: 0 | CT10: 0.32 | CU10: 0.25 | CV10: 0.17 | CW10: 0.29 | CX10: 0.21 | CY10: 0.72 | CZ10: 0 | DA10: 0.32 | DB10: 0.33 | DC10: 0.17 | DD10: 0.23 | DE10: 0 | DF10: 0.64 | DG10: 0 | DH10: 0.32 | DI10: 0.25 | DJ10: 0.17 | DK10: 0.25 | DL10: 0 | DM10: 0.57 | DN10: 0 | DO10: 0.32 | DP10: 0.33 | DQ10: 0.25 | DR10: 0.3 | DS10: 0 | DT10: 0.58 | DU10: 0 | DV10: 0.41 | DW10: 0.42 | DX10: 0.42 | DY10: 0.29 | DZ10: 0.29 | EA10: 0.59 | EB10: 0 | EC10: 0.36 | ED10: 0.33 | EE10: 0.17 | EF10: 0.3 | EG10: 0.29 | EH10: 0.62 | EI10: 0 | EJ10: 0.36 | EK10: 0.33 | EL10: 0.17 | EM10: 0.34 | EN10: 0.42 | EO10: 0.67 | EP10: 0 | EQ10: 0.27 | ER10: 0.33 | ES10: 0.33 | ET10: 0.32 | EU10: 0.42 | EV10: 0.55 | EW10: 0 | EX10: 0.27 | EY10: 0.33 | EZ10: 0.33
A11: HND | B11: Honduras | C11: 0.52 | D11: 0.58 | E11: 0.75 | F11: 0.5 | G11: 0.64 | H11: 0.42 | I11: 0.25 | J11: 0.53 | K11: 0.54 | L11: 0.73 | M11: 0.5 | N11: 0.64 | O11: 0.42 | P11: 0.33 | Q11: 0.51 | R11: 0.58 | S11: 0.73 | T11: 0.5 | U11: 0.59 | V11: 0.33 | W11: 0.33 | X11: 0.54 | Y11: 0.58 | Z11: 0.75 | AA11: 0.5 | AB11: 0.64 | AC11: 0.33 | AD11: 0.42 | AE11: 0.51 | AF11: 0.58 | AG11: 0.73 | AH11: 0.5 | AI11: 0.59 | AJ11: 0.33 | AK11: 0.33 | AL11: 0.52 | AM11: 0.58 | AN11: 0.75 | AO11: 0.5 | AP11: 0.59 | AQ11: 0.25 | AR11: 0.42 | AS11: 0.52 | AT11: 0.58 | AU11: 0.78 | AV11: 0.5 | AW11: 0.59 | AX11: 0.25 | AY11: 0.42 | AZ11: 0.5 | BA11: 0.63 | BB11: 0.77 | BC11: 0.5 | BD11: 0.55 | BE11: 0.25 | BF11: 0.33 | BG11: 0.49 | BH11: 0.67 | BI11: 0.75 | BJ11: 0.5 | BK11: 0.55 | BL11: 0.25 | BM11: 0.25 | BN11: 0.48 | BO11: 0.63 | BP11: 0.78 | BQ11: 0.5 | BR11: 0.5 | BS11: 0.25 | BT11: 0.25 | BU11: 0.51 | BV11: 0.63 | BW11: 0.79 | BX11: 0.5 | BY11: 0.5 | BZ11: 0.33 | CA11: 0.33 | CB11: 0.5 | CC11: 0.63 | CD11: 0.77 | CE11: 0.5 | CF11: 0.5 | CG11: 0.25 | CH11: 0.33 | CI11: 0.49 | CJ11: 0.58 | CK11: 0.78 | CL11: 0.5 | CM11: 0.5 | CN11: 0.25 | CO11: 0.33 | CP11: 0.49 | CQ11: 0.63 | CR11: 0.74 | CS11: 0.5 | CT11: 0.5 | CU11: 0.25 | CV11: 0.33 | CW11: 0.5 | CX11: 0.67 | CY11: 0.77 | CZ11: 0.5 | DA11: 0.5 | DB11: 0.25 | DC11: 0.33 | DD11: 0.51 | DE11: 0.67 | DF11: 0.78 | DG11: 0.5 | DH11: 0.55 | DI11: 0.25 | DJ11: 0.33 | DK11: 0.51 | DL11: 0.67 | DM11: 0.73 | DN11: 0.5 | DO11: 0.59 | DP11: 0.25 | DQ11: 0.33 | DR11: 0.51 | DS11: 0.58 | DT11: 0.78 | DU11: 0.5 | DV11: 0.59 | DW11: 0.25 | DX11: 0.33 | DY11: 0.53 | DZ11: 0.58 | EA11: 0.8 | EB11: 0.5 | EC11: 0.64 | ED11: 0.25 | EE11: 0.42 | EF11: 0.53 | EG11: 0.58 | EH11: 0.79 | EI11: 0.5 | EJ11: 0.64 | EK11: 0.25 | EL11: 0.42 | EM11: 0.53 | EN11: 0.58 | EO11: 0.82 | EP11: 0.5 | EQ11: 0.64 | ER11: 0.33 | ES11: 0.33 | ET11: 0.52 | EU11: 0.5 | EV11: 0.84 | EW11: 0.5 | EX11: 0.64 | EY11: 0.33 | EZ11: 0.33
A12: IND | B12: India | C12: 0.68 | D12: 0.83 | E12: 0.63 | F12: 0.75 | G12: 0.73 | H12: 0.75 | I12: 0.42 | J12: 0.67 | K12: 0.83 | L12: 0.57 | M12: 0.75 | N12: 0.73 | O12: 0.75 | P12: 0.42 | Q12: 0.67 | R12: 0.83 | S12: 0.56 | T12: 0.75 | U12: 0.73 | V12: 0.75 | W12: 0.42 | X12: 0.65 | Y12: 0.83 | Z12: 0.54 | AA12: 0.75 | AB12: 0.64 | AC12: 0.75 | AD12: 0.42 | AE12: 0.67 | AF12: 0.83 | AG12: 0.56 | AH12: 0.75 | AI12: 0.68 | AJ12: 0.75 | AK12: 0.42 | AL12: 0.67 | AM12: 0.83 | AN12: 0.58 | AO12: 0.75 | AP12: 0.68 | AQ12: 0.75 | AR12: 0.42 | AS12: 0.67 | AT12: 0.83 | AU12: 0.56 | AV12: 0.75 | AW12: 0.68 | AX12: 0.75 | AY12: 0.42 | AZ12: 0.64 | BA12: 0.83 | BB12: 0.58 | BC12: 0.75 | BD12: 0.59 | BE12: 0.67 | BF12: 0.42 | BG12: 0.63 | BH12: 0.83 | BI12: 0.52 | BJ12: 0.75 | BK12: 0.59 | BL12: 0.67 | BM12: 0.42 | BN12: 0.63 | BO12: 0.83 | BP12: 0.54 | BQ12: 0.75 | BR12: 0.59 | BS12: 0.67 | BT12: 0.42 | BU12: 0.63 | BV12: 0.83 | BW12: 0.52 | BX12: 0.75 | BY12: 0.68 | BZ12: 0.67 | CA12: 0.33 | CB12: 0.65 | CC12: 0.83 | CD12: 0.55 | CE12: 0.75 | CF12: 0.68 | CG12: 0.67 | CH12: 0.42 | CI12: 0.66 | CJ12: 0.83 | CK12: 0.62 | CL12: 0.75 | CM12: 0.68 | CN12: 0.67 | CO12: 0.42 | CP12: 0.65 | CQ12: 0.83 | CR12: 0.57 | CS12: 0.75 | CT12: 0.68 | CU12: 0.67 | CV12: 0.42 | CW12: 0.65 | CX12: 0.83 | CY12: 0.56 | CZ12: 0.75 | DA12: 0.68 | DB12: 0.67 | DC12: 0.42 | DD12: 0.66 | DE12: 0.83 | DF12: 0.6 | DG12: 0.75 | DH12: 0.68 | DI12: 0.67 | DJ12: 0.42 | DK12: 0.67 | DL12: 0.83 | DM12: 0.6 | DN12: 0.75 | DO12: 0.77 | DP12: 0.67 | DQ12: 0.42 | DR12: 0.67 | DS12: 0.83 | DT12: 0.64 | DU12: 0.75 | DV12: 0.73 | DW12: 0.67 | DX12: 0.42 | DY12: 0.63 | DZ12: 0.83 | EA12: 0.61 | EB12: 0.75 | EC12: 0.68 | ED12: 0.67 | EE12: 0.25 | EF12: 0.62 | EG12: 0.83 | EH12: 0.56 | EI12: 0.75 | EJ12: 0.64 | EK12: 0.67 | EL12: 0.25 | EM12: 0.59 | EN12: 0.75 | EO12: 0.49 | EP12: 0.75 | EQ12: 0.36 | ER12: 0.67 | ES12: 0.5 | ET12: 0.62 | EU12: 0.83 | EV12: 0.58 | EW12: 0.75 | EX12: 0.36 | EY12: 0.67 | EZ12: 0.5
A13: JOR | B13: Jordan | C13: 0.55 | D13: 0.54 | E13: 0.62 | F13: 0.5 | G13: 0.64 | H13: 0.58 | I13: 0.42 | J13: 0.57 | K13: 0.54 | L13: 0.65 | M13: 0.5 | N13: 0.64 | O13: 0.58 | P13: 0.5 | Q13: 0.57 | R13: 0.58 | S13: 0.63 | T13: 0.5 | U13: 0.59 | V13: 0.58 | W13: 0.5 | X13: 0.56 | Y13: 0.58 | Z13: 0.62 | AA13: 0.5 | AB13: 0.59 | AC13: 0.58 | AD13: 0.5 | AE13: 0.57 | AF13: 0.58 | AG13: 0.61 | AH13: 0.5 | AI13: 0.64 | AJ13: 0.58 | AK13: 0.5 | AL13: 0.59 | AM13: 0.63 | AN13: 0.61 | AO13: 0.5 | AP13: 0.64 | AQ13: 0.67 | AR13: 0.5 | AS13: 0.61 | AT13: 0.63 | AU13: 0.62 | AV13: 0.5 | AW13: 0.73 | AX13: 0.67 | AY13: 0.5 | AZ13: 0.61 | BA13: 0.63 | BB13: 0.62 | BC13: 0.5 | BD13: 0.73 | BE13: 0.67 | BF13: 0.5 | BG13: 0.6 | BH13: 0.63 | BI13: 0.69 | BJ13: 0.5 | BK13: 0.73 | BL13: 0.67 | BM13: 0.42 | BN13: 0.59 | BO13: 0.63 | BP13: 0.66 | BQ13: 0.5 | BR13: 0.68 | BS13: 0.67 | BT13: 0.42 | BU13: 0.63 | BV13: 0.63 | BW13: 0.67 | BX13: 0.5 | BY13: 0.82 | BZ13: 0.67 | CA13: 0.5 | CB13: 0.65 | CC13: 0.67 | CD13: 0.76 | CE13: 0.5 | CF13: 0.82 | CG13: 0.67 | CH13: 0.5 | CI13: 0.66 | CJ13: 0.67 | CK13: 0.8 | CL13: 0.5 | CM13: 0.82 | CN13: 0.67 | CO13: 0.5 | CP13: 0.66 | CQ13: 0.67 | CR13: 0.82 | CS13: 0.5 | CT13: 0.82 | CU13: 0.67 | CV13: 0.5 | CW13: 0.67 | CX13: 0.67 | CY13: 0.85 | CZ13: 0.5 | DA13: 0.82 | DB13: 0.67 | DC13: 0.5 | DD13: 0.69 | DE13: 0.79 | DF13: 0.86 | DG13: 0.5 | DH13: 0.82 | DI13: 0.67 | DJ13: 0.5 | DK13: 0.68 | DL13: 0.79 | DM13: 0.83 | DN13: 0.5 | DO13: 0.82 | DP13: 0.67 | DQ13: 0.5 | DR13: 0.68 | DS13: 0.79 | DT13: 0.83 | DU13: 0.5 | DV13: 0.77 | DW13: 0.67 | DX13: 0.5 | DY13: 0.67 | DZ13: 0.79 | EA13: 0.8 | EB13: 0.5 | EC13: 0.77 | ED13: 0.67 | EE13: 0.5 | EF13: 0.66 | EG13: 0.75 | EH13: 0.79 | EI13: 0.5 | EJ13: 0.77 | EK13: 0.67 | EL13: 0.5 | EM13: 0.67 | EN13: 0.75 | EO13: 0.78 | EP13: 0.5 | EQ13: 0.82 | ER13: 0.67 | ES13: 0.5 | ET13: 0.71 | EU13: 0.75 | EV13: 0.84 | EW13: 0.5 | EX13: 0.82 | EY13: 0.67 | EZ13: 0.67
... A29: ZMB | B29: Zambia | C29: 0.56 | D29: 0.79 | E29: 0.73 | F29: 0.25 | G29: 0.59 | H29: 0.67 | I29: 0.33 | J29: 0.53 | K29: 0.75 | L29: 0.71 | M29: 0.25 | N29: 0.45 | O29: 0.67 | P29: 0.33 | Q29: 0.54 | R29: 0.75 | S29: 0.71 | T29: 0.25 | U29: 0.45 | V29: 0.67 | W29: 0.42 | X29: 0.54 | Y29: 0.75 | Z29: 0.72 | AA29: 0.25 | AB29: 0.5 | AC29: 0.67 | AD29: 0.33 | AE29: 0.55 | AF29: 0.75 | AG29: 0.74 | AH29: 0.25 | AI29: 0.55 | AJ29: 0.67 | AK29: 0.33 | AL29: 0.57 | AM29: 0.75 | AN29: 0.77 | AO29: 0.25 | AP29: 0.55 | AQ29: 0.67 | AR29: 0.42 | AS29: 0.56 | AT29: 0.75 | AU29: 0.73 | AV29: 0.25 | AW29: 0.55 | AX29: 0.67 | AY29: 0.42 | AZ29: 0.55 | BA29: 0.75 | BB29: 0.71 | BC29: 0.25 | BD29: 0.5 | BE29: 0.67 | BF29: 0.42 | BG29: 0.55 | BH29: 0.75 | BI29: 0.71 | BJ29: 0.25 | BK29: 0.5 | BL29: 0.67 | BM29: 0.42 | BN29: 0.55 | BO29: 0.75 | BP29: 0.79 | BQ29: 0.25 | BR29: 0.45 | BS29: 0.67 | BT29: 0.42 | BU29: 0.56 | BV29: 0.75 | BW29: 0.77 | BX29: 0.25 | BY29: 0.45 | BZ29: 0.67 | CA29: 0.5 | CB29: 0.57 | CC29: 0.75 | CD29: 0.78 | CE29: 0.25 | CF29: 0.45 | CG29: 0.67 | CH29: 0.5 | CI29: 0.57 | CJ29: 0.75 | CK29: 0.78 | CL29: 0.25 | CM29: 0.45 | CN29: 0.67 | CO29: 0.5 | CP29: 0.57 | CQ29: 0.75 | CR29: 0.79 | CS29: 0.25 | CT29: 0.45 | CU29: 0.67 | CV29: 0.5 | CW29: 0.58 | CX29: 0.75 | CY29: 0.78 | CZ29: 0.25 | DA29: 0.45 | DB29: 0.67 | DC29: 0.58 | DD29: 0.57 | DE29: 0.75 | DF29: 0.77 | DG29: 0.25 | DH29: 0.5 | DI29: 0.67 | DJ29: 0.5 | DK29: 0.59 | DL29: 0.79 | DM29: 0.78 | DN29: 0.25 | DO29: 0.55 | DP29: 0.67 | DQ29: 0.5 | DR29: 0.57 | DS29: 0.79 | DT29: 0.78 | DU29: 0.25 | DV29: 0.45 | DW29: 0.67 | DX29: 0.5 | DY29: 0.52 | DZ29: 0.75 | EA29: 0.69 | EB29: 0.25 | EC29: 0.45 | ED29: 0.67 | EE29: 0.33 | EF29: 0.51 | EG29: 0.75 | EH29: 0.61 | EI29: 0.25 | EJ29: 0.45 | EK29: 0.67 | EL29: 0.33 | EM29: 0.6 | EN29: 0.75 | EO29: 0.78 | EP29: 0.25 | EQ29: 0.82 | ER29: 0.67 | ES29: 0.33 | ET29: 0.65 | EU29: 0.75 | EV29: 0.89 | EW29: 0.25 | EX29: 0.82 | EY29: 0.67 | EZ29: 0.5
E37: PRS21VA | F37: meaning
E38: PRS-data source PRS org ICRG
E40: VA | F40: Voice and Accountability (Military in politics, Democratic accountability)
E42: PV | F42: Political Stability and Absence of Violence (Government stability, Internal conflict, External conflict, Ethnic tensions)
E44: GE | F44: Government Effectiveness (Bureaucratic quality)
E46: RQ | F46: Regulatory Quality (Investment profile)
E48: RL | F48: Rule of Law (Law and order)
E50: CC | F50: Control of Corruption (Corruption)

Sheet Graphs of FD & INST

Sheet FDxINST
A1: Country | C1: Country code | D1: Data type | E1: 2000 [YR2000] | F1: 2001 [YR2001] | G1: 2002 [YR2002] | H1: 2003 [YR2003] | I1: 2004 [YR2004] | J1: 2005 [YR2005] | K1: 2006 [YR2006] | L1: 2007 [YR2007] | M1: 2008 [YR2008] | N1: 2009 [YR2009] | O1: 2010 [YR2010] | P1: 2011 [YR2011] | Q1: 2012 [YR2012] | R1: 2013 [YR2013] | S1: 2014 [YR2014] | T1: 2015 [YR2015] | U1: 2016 [YR2016] | V1: 2017 [YR2017] | W1: 2018 [YR2018] | X1: 2019 [YR2019] | Y1: 2020 [YR2020] | Z1: 2021 [YR2021] | AB1: Average
A2: Angola | C2: AGO | D2: FD*INST | E2: =FD!E2*INST!B2 -> 0.0342 | F2: =FD!F2*INST!C2 -> 0.0324 | G2: =FD!G2*INST!D2 -> 0.046 | H2: =FD!H2*INST!E2 -> 0.048 | I2: =FD!I2*INST!F2 -> 0.0506 | J2: =FD!J2*INST!G2 -> 0.0506 | K2: =FD!K2*INST!H2 -> 0.0564 | L2: =FD!L2*INST!I2 -> 0.0624 | ... Z2: =FD!Z2*INST!W2 -> 0.0686 | AB2: =AVERAGE(E2:Z2) -> 0.05775
A3: Bangladesh | C3: BGD | D3: FD*INST | E3: =FD!E3*INST!B3 -> 0.121 | F3: =FD!F3*INST!C3 -> 0.095 | G3: =FD!G3*INST!D3 -> 0.08 | H3: =FD!H3*INST!E3 -> 0.084 | I3: =FD!I3*INST!F3 -> 0.0798 | J3: =FD!J3*INST!G3 -> 0.0752 | K3: =FD!K3*INST!H3 -> 0.063 | L3: =FD!L3*INST!I3 -> 0.0705 | ... Z3: =FD!Z3*INST!W3 -> 0.1224 | AB3: =AVERAGE(E3:Z3) -> 0.10241818
A4: Bolivia | C4: BOL | D4: FD*INST | E4: =FD!E4*INST!B4 -> 0.066 | F4: =FD!F4*INST!C4 -> 0.0671 | G4: =FD!G4*INST!D4 -> 0.0672 | H4: =FD!H4*INST!E4 -> 0.0855 | I4: =FD!I4*INST!F4 -> 0.078 | J4: =FD!J4*INST!G4 -> 0.075 | K4: =FD!K4*INST!H4 -> 0.0768 | L4: =FD!L4*INST!I4 -> 0.0846 | ... Z4: =FD!Z4*INST!W4 -> 0.1833 | AB4: =AVERAGE(E4:Z4) -> 0.11207273
A5: Cameroon | C5: CMR | D5: FD*INST | E5: =FD!E5*INST!B5 -> 0.0384 | F5: =FD!F5*INST!C5 -> 0.036 | G5: =FD!G5*INST!D5 -> 0.0344 | H5: =FD!H5*INST!E5 -> 0.0294 | I5: =FD!I5*INST!F5 -> 0.0329 | J5: =FD!J5*INST!G5 -> 0.0392 | K5: =FD!K5*INST!H5 -> 0.0432 | L5: =FD!L5*INST!I5 -> 0.0495 | ... Z5: =FD!Z5*INST!W5 -> 0.041 | AB5: =AVERAGE(E5:Z5) -> 0.03915
A6: Congo, Rep. of | C6: COG | D6: FD*INST | E6: =FD!E6*INST!B6 -> 0.014 | F6: =FD!F6*INST!C6 -> 0.021 | G6: =FD!G6*INST!D6 -> 0.0172 | H6: =FD!H6*INST!E6 -> 0.0252 | I6: =FD!I6*INST!F6 -> 0.0172 | J6: =FD!J6*INST!G6 -> 0.0129 | K6: =FD!K6*INST!H6 -> 0.0132 | L6: =FD!L6*INST!I6 -> 0.0132 | ... Z6: =FD!Z6*INST!W6 -> 0.0378 | AB6: =AVERAGE(E6:Z6) -> 0.031454545
A7: Côte d'Ivoire | C7: CIV | D7: FD*INST | E7: =FD!E7*INST!B7 -> 0.0784 | F7: =FD!F7*INST!C7 -> 0.0408 | G7: =FD!G7*INST!D7 -> 0.035 | H7: =FD!H7*INST!E7 -> 0.037 | I7: =FD!I7*INST!F7 -> 0.0352 | J7: =FD!J7*INST!G7 -> 0.0319 | K7: =FD!K7*INST!H7 -> 0.0403 | L7: =FD!L7*INST!I7 -> 0.0462 | ... Z7: =FD!Z7*INST!W7 -> 0.0559 | AB7: =AVERAGE(E7:Z7) -> 0.052154545
A8: Egypt, Arab Rep. of | C8: EGY | D8: FD*INST | E8: =FD!E8*INST!B8 -> 0.174 | F8: =FD!F8*INST!C8 -> 0.1829 | G8: =FD!G8*INST!D8 -> 0.1749 | H8: =FD!H8*INST!E8 -> 0.1782 | I8: =FD!I8*INST!F8 -> 0.1802 | J8: =FD!J8*INST!G8 -> 0.2268 | K8: =FD!K8*INST!H8 -> 0.1998 | L8: =FD!L8*INST!I8 -> 0.1924 | ... Z8: =FD!Z8*INST!W8 -> 0.1612 | AB8: =AVERAGE(E8:Z8) -> 0.16442273
A9: Ghana | C9: GHA | D9: FD*INST | E9: =FD!E9*INST!B9 -> 0.0648 | F9: =FD!F9*INST!C9 -> 0.06 | G9: =FD!G9*INST!D9 -> 0.0539 | H9: =FD!H9*INST!E9 -> 0.0588 | I9: =FD!I9*INST!F9 -> 0.0728 | J9: =FD!J9*INST!G9 -> 0.066 | K9: =FD!K9*INST!H9 -> 0.0627 | L9: =FD!L9*INST!I9 -> 0.0672 | ... Z9: =FD!Z9*INST!W9 -> 0.1026 | AB9: =AVERAGE(E9:Z9) -> 0.079522727
A10: Haiti | C10: HTI | D10: FD*INST | E10: =FD!E10*INST!B10 -> 0.0288 | F10: =FD!F10*INST!C10 -> 0.0306 | G10: =FD!G10*INST!D10 -> 0.027 | H10: =FD!H10*INST!E10 -> 0.0261 | I10: =FD!I10*INST!F10 -> 0.027 | J10: =FD!J10*INST!G10 -> 0.015 | K10: =FD!K10*INST!H10 -> 0.0138 | L10: =FD!L10*INST!I10 -> 0.0174 | ... Z10: =FD!Z10*INST!W10 -> 0.028 | AB10: =AVERAGE(E10:Z10) -> 0.025281818
A11: Honduras | C11: HND | D11: FD*INST | E11: =FD!E11*INST!B11 -> 0.0676 | F11: =FD!F11*INST!C11 -> 0.0795 | G11: =FD!G11*INST!D11 -> 0.0742 | H11: =FD!H11*INST!E11 -> 0.0848 | I11: =FD!I11*INST!F11 -> 0.0765 | J11: =FD!J11*INST!G11 -> 0.0816 | K11: =FD!K11*INST!H11 -> 0.0918 | L11: =FD!L11*INST!I11 -> 0.095 | ... Z11: =FD!Z11*INST!W11 -> 0.1092 | AB11: =AVERAGE(E11:Z11) -> 0.094509091
A12: India | C12: IND | D12: FD*INST | E12: =FD!E12*INST!B12 -> 0.2728 | F12: =FD!F12*INST!C12 -> 0.2478 | G12: =FD!G12*INST!D12 -> 0.2666 | H12: =FD!H12*INST!E12 -> 0.2709 | I12: =FD!I12*INST!F12 -> 0.3015 | J12: =FD!J12*INST!G12 -> 0.3015 | K12: =FD!K12*INST!H12 -> 0.3102 | L12: =FD!L12*INST!I12 -> 0.2925 | ... Z12: =FD!Z12*INST!W12 -> 0.3604 | AB12: =AVERAGE(E12:Z12) -> 0.29815909
A13: Jordan | C13: JOR | D13: FD*INST | E13: =FD!E13*INST!B13 -> 0.3763 | F13: =FD!F13*INST!C13 -> 0.3551 | G13: =FD!G13*INST!D13 -> 0.3498 | H13: =FD!H13*INST!E13 -> 0.3484 | I13: =FD!I13*INST!F13 -> 0.3604 | J13: =FD!J13*INST!G13 -> 0.3672 | K13: =FD!K13*INST!H13 -> 0.345 | L13: =FD!L13*INST!I13 -> 0.3417 | ... Z13: =FD!Z13*INST!W13 -> 0.198 | AB13: =AVERAGE(E13:Z13) -> 0.28574545
... A28: Zambia | C28: ZMB | D28: FD*INST | E28: =FD!E28*INST!B28 -> 0.091 | F28: =FD!F28*INST!C28 -> 0.084 | G28: =FD!G28*INST!D28 -> 0.0867 | H28: =FD!H28*INST!E28 -> 0.0728 | I28: =FD!I28*INST!F28 -> 0.0912 | J28: =FD!J28*INST!G28 -> 0.0885 | K28: =FD!K28*INST!H28 -> 0.0969 | L28: =FD!L28*INST!I28 -> 0.1044 | ... Z28: =FD!Z28*INST!W28 -> 0.112 | AB28: =AVERAGE(E28:Z28) -> 0.098318182

Sheet REN
A1: Country Name | B1: 2000 [YR2000] | C1: 2001 [YR2001] | D1: 2002 [YR2002] | E1: 2003 [YR2003] | F1: 2004 [YR2004] | G1: 2005 [YR2005] | H1: 2006 [YR2006] | I1: 2007 [YR2007] | J1: 2008 [YR2008] | K1: 2009 [YR2009] | L1: 2010 [YR2010] | M1: 2011 [YR2011] | N1: 2012 [YR2012] | O1: 2013 [YR2013] | P1: 2014 [YR2014] | Q1: 2015 [YR2015] | R1: 2016 [YR2016] | S1: 2017 [YR2017] | T1: 2018 [YR2018] | U1: 2019 [YR2019] | V1: 2020 [YR2020] | W1: 2021 [YR2021] | Y1: average
A2: Angola | B2: 73.8 | C2: 72.8 | D2: 70.8 | E2: 65.6 | F2: 62.3 | G2: 68.9 | H2: 62.6 | I2: 58.9 | J2: 55.4 | K2: 53 | L2: 53.1 | M2: 51.7 | N2: 49 | O2: 46.8 | P2: 47.5 | Q2: 47.1 | R2: 48.1 | S2: 52.5 | T2: 52.5 | U2: 51 | V2: 60.1 | W2: 52.9 | Y2: =AVERAGE(B2:W2) -> 57.109091
A3: Bangladesh | B3: 60.2 | C3: 55.9 | D3: 54.4 | E3: 52.6 | F3: 52 | G3: 50.6 | H3: 48.6 | I3: 47.2 | J3: 45.2 | K3: 43.1 | L3: 40.3 | M3: 38.4 | N3: 37.3 | O3: 37 | P3: 35.4 | Q3: 33.1 | R3: 30.2 | S3: 28.1 | T3: 27 | U3: 26.1 | V3: 27.2 | W3: 25 | Y3: =AVERAGE(B3:W3) -> 40.677273
A4: Bolivia | B4: 29.2 | C4: 29 | D4: 28.1 | E4: 27 | F4: 25.8 | G4: 24.6 | H4: 23.7 | I4: 22.1 | J4: 21.3 | K4: 20.6 | L4: 19.9 | M4: 18.1 | N4: 17.4 | O4: 16 | P4: 15 | Q4: 14.2 | R4: 13.6 | S4: 14.3 | T4: 14.3 | U4: 13.5 | V4: 16.9 | W4: 12.8 | Y4: =AVERAGE(B4:W4) -> 19.881818
A5: Cameroon | B5: 84.6 | C5: 85.3 | D5: 85.2 | E5: 85.3 | F5: 85.5 | G5: 86.3 | H5: 85.5 | I5: 80.8 | J5: 80.8 | K5: 79.2 | L5: 78.7 | M5: 78.6 | N5: 78.6 | O5: 77.7 | P5: 76.9 | Q5: 78.1 | R5: 78.8 | S5: 79.2 | T5: 78.7 | U5: 78.9 | V5: 78.9 | W5: 79.2 | Y5: =AVERAGE(B5:W5) -> 80.945455
A6: Congo, Rep. | B6: 64.9 | C6: 61.2 | D6: 68.6 | E6: 62.1 | F6: 63.1 | G6: 63.1 | H6: 69.3 | I6: 60.2 | J6: 56.8 | K6: 55.9 | L6: 54.5 | M6: 64.3 | N6: 65.1 | O6: 62.3 | P6: 62.1 | Q6: 64.2 | R6: 67.7 | S6: 69.8 | T6: 70.6 | U6: 69.8 | V6: 71.4 | W6: 71.4 | Y6: =AVERAGE(B6:W6) -> 64.472727
A7: Cote d'Ivoire | B7: 63.7 | C7: 64.7 | D7: 65.3 | E7: 70.3 | F7: 75.4 | G7: 77.9 | H7: 74.8 | I7: 76.3 | J7: 74.2 | K7: 73.7 | L7: 75.4 | M7: 79.1 | N7: 74.9 | O7: 72.2 | P7: 71.9 | Q7: 64.5 | R7: 64 | S7: 62.5 | T7: 60.5 | U7: 61.1 | V7: 61.8 | W7: 58.2 | Y7: =AVERAGE(B7:W7) -> 69.2
A8: Egypt, Arab Rep. | B8: 8.3 | C8: 7.8 | D8: 7.3 | E8: 7.4 | F8: 7.6 | G8: 6.5 | H8: 6.2 | I8: 6 | J8: 5.9 | K8: 5.7 | L8: 5.4 | M8: 5.4 | N8: 5.3 | O8: 5.3 | P8: 5.4 | Q8: 5.3 | R8: 5.1 | S8: 4.9 | T8: 5 | U8: 6.2 | V8: 6.7 | W8: 6.1 | Y8: =AVERAGE(B8:W8) -> 6.1272727
A9: Ghana | B9: 71.6 | C9: 69.3 | D9: 65.7 | E9: 64.5 | F9: 62.4 | G9: 61.4 | H9: 58.6 | I9: 54.5 | J9: 57.3 | K9: 51.9 | L9: 51.9 | M9: 50.1 | N9: 46.5 | O9: 46.2 | P9: 47.7 | Q9: 44 | R9: 45.2 | S9: 45.3 | T9: 42.1 | U9: 42.6 | V9: 40 | W9: 39 | Y9: =AVERAGE(B9:W9) -> 52.627273
A10: Haiti | B10: 80.8 | C10: 80.9 | D10: 79.1 | E10: 79 | F10: 81.1 | G10: 81.1 | H10: 81.4 | I10: 79.3 | J10: 79.6 | K10: 80.3 | L10: 79 | M10: 79 | N10: 82.2 | O10: 80.4 | P10: 77.8 | Q10: 76.1 | R10: 76.1 | S10: 76.2 | T10: 76.2 | U10: 76.4 | V10: 76.3 | W10: 76.7 | Y10: =AVERAGE(B10:W10) -> 78.863636
A11: Honduras | B11: 55.2 | C11: 50.4 | D11: 49.8 | E11: 47.9 | F11: 46.7 | G11: 51.4 | H11: 52.2 | I11: 50.6 | J11: 50 | K11: 50.5 | L11: 53.6 | M11: 50.9 | N11: 49.3 | O11: 51.1 | P11: 52.2 | Q11: 50.8 | R11: 52.7 | S11: 45.6 | T11: 48.9 | U11: 46.2 | V11: 50.2 | W11: 45.9 | Y11: =AVERAGE(B11:W11) -> 50.095455
A12: India | B12: 46.9 | C12: 47.1 | D12: 45.8 | E12: 45.6 | F12: 44.9 | G12: 44.2 | H12: 43.2 | I12: 41.5 | J12: 39.4 | K12: 37.4 | L12: 36.2 | M12: 35 | N12: 34.8 | O12: 34.9 | P12: 33.9 | Q12: 33.4 | R12: 33 | S12: 32.5 | T12: 32.9 | U12: 33.5 | V12: 36.1 | W12: 34.9 | Y12: =AVERAGE(B12:W12) -> 38.504545
A13: Jordan | B13: 2.1 | C13: 2.1 | D13: 2.1 | E13: 2 | F13: 1.8 | G13: 1.7 | H13: 2.3 | I13: 2.3 | J13: 2.7 | K13: 2.8 | L13: 3 | M13: 3 | N13: 2.9 | O13: 3.1 | P13: 3.1 | Q13: 3.2 | R13: 4.7 | S13: 5.3 | T13: 7.2 | U13: 8.5 | V13: 10.7 | W13: 11.5 | Y13: =AVERAGE(B13:W13) -> 4.0045455
... A28: Zambia | B28: 90 | C28: 89.8 | D28: 89.6 | E28: 89.3 | F28: 89.4 | G28: 88.9 | H28: 89.7 | I28: 90.7 | J28: 89.8 | K28: 89.2 | L28: 89.2 | M28: 87.9 | N28: 85.4 | O28: 85.3 | P28: 84.6 | Q28: 84 | R28: 84 | S28: 83.5 | T28: 83.8 | U28: 86.1 | V28: 85.4 | W28: 83 | Y28: =AVERAGE(B28:W28) -> 87.209091

Sheet RGDPPC
A1: Series Name | B1: Series Code | C1: Country Name | D1: Country Code | E1: 2000 [YR2000] | F1: 2001 [YR2001] | G1: 2002 [YR2002] | H1: 2003 [YR2003] | I1: 2004 [YR2004] | J1: 2005 [YR2005] | K1: 2006 [YR2006] | L1: 2007 [YR2007] | M1: 2008 [YR2008] | N1: 2009 [YR2009] | O1: 2010 [YR2010] | P1: 2011 [YR2011] | Q1: 2012 [YR2012] | R1: 2013 [YR2013] | S1: 2014 [YR2014] | T1: 2015 [YR2015] | U1: 2016 [YR2016] | V1: 2017 [YR2017] | W1: 2018 [YR2018] | X1: 2019 [YR2019] | Y1: 2020 [YR2020] | Z1: 2021 [YR2021] | AB1: Average
A2: GDP per capita (constant 2015 US$) | B2: NY.GDP.PCAP.KD | C2: Angola | D2: AGO | E2: 3736444.5 | F2: 3794145.8 | G2: 4579054.7 | H2: 4529217.3 | I2: 5188677.9 | J2: 6382750.4 | K2: 7378030.5 | L2: 8898538.8 | M2: 10197086 | N2: 9613777.9 | O2: 9701331.7 | P2: 9609642.2 | Q2: 10475417 | R2: 10684000 | S2: 10894852 | T2: 10329170 | U2: 9126340.3 | V2: 8477419.5 | W2: 7704768.2 | X2: 7099232.6 | Y2: 5921320.6 | Z2: 5690366.1 | AB2: =AVERAGE(E2:Z2) -> 7727799.3
A3: GDP per capita (constant 2015 US$) | B3: NY.GDP.PCAP.KD | C3: Bangladesh | D3: BGD | E3: 385095.3 | F3: 411251.48 | G3: 429905.95 | H3: 458093.78 | I3: 493725.96 | J3: 546422.14 | K3: 607494.87 | L3: 681463.84 | M3: 750749.74 | N3: 813116.32 | O3: 890502.18 | P3: 991179.43 | Q3: 1103322.1 | R3: 1216955.3 | S3: 1344225.8 | T3: 1499122.2 | U3: 1689560.4 | V3: 1887199.1 | W3: 2138176.5 | X3: 2446746.7 | Y3: 2574952.7 | Z3: 2897077.3 | AB3: =AVERAGE(E3:Z3) -> 1193470
A4: GDP per capita (constant 2015 US$) | B4: NY.GDP.PCAP.KD | C4: Bolivia | D4: BOL | E4: 4056962.3 | F4: 4055574.9 | G4: 4119560 | H4: 4202792.5 | I4: 4409961.4 | J4: 4649141.1 | K4: 4934738.9 | L4: 5214040.4 | M4: 5679882.1 | N4: 5868873.5 | O4: 6157380.7 | P4: 6597297.6 | Q4: 7060918.3 | R4: 7803723.6 | S4: 8415234.8 | T4: 8976093.3 | U4: 9471440.6 | V4: 9986637.8 | W4: 10541479 | X4: 10708482 | Y4: 8701435.4 | Z4: 9599776.6 | AB4: =AVERAGE(E4:Z4) -> 6873246.7
A5: GDP per capita (constant 2015 US$) | B5: NY.GDP.PCAP.KD | C5: Cameroon | D5: CMR | E5: 1325438.5 | F5: 1368728.5 | G5: 1416021.6 | H5: 1491071.7 | I5: 1617330.9 | J5: 1599576 | K5: 1631571.7 | L5: 1678918 | M5: 1677082.3 | N5: 1666421.8 | O5: 1666426.4 | P5: 1683004.1 | Q5: 1741527.9 | R5: 1814983 | S5: 1909424.8 | T5: 2002225.3 | U5: 2060999.9 | V5: 2087755.7 | W5: 2134578.6 | X5: 2161834.6 | Y5: 2057845.2 | Z5: 2083911.7 | AB5: =AVERAGE(E5:Z5) -> 1767121.7
